2024-12-01 11:53:55,634 - src.main - ERROR - Validation error: [{'type': 'missing', 'loc': ('body', 'username'), 'msg': 'Field required', 'input': {'email': 'test@example.com', 'password': 'Test@123', 'first_name': 'Test', 'last_name': 'User'}}, {'type': 'missing', 'loc': ('body', 'full_name'), 'msg': 'Field required', 'input': {'email': 'test@example.com', 'password': 'Test@123', 'first_name': 'Test', 'last_name': 'User'}}] - [C:\Users\ahmed\OneDrive\Desktop\Graduation_project\src\main.py:74]
2024-12-01 11:53:55,636 - src.main - ERROR - Unhandled error: type object 'SecurityHeaders' has no attribute 'get_security_headers' - [C:\Users\ahmed\OneDrive\Desktop\Graduation_project\src\main.py:95]
  + Exception Group Traceback (most recent call last):
  |   File "c:\Users\ahmed\OneDrive\Desktop\Graduation_project\venv312\Lib\site-packages\starlette\_utils.py", line 76, in collapse_excgroups
  |     yield
  |   File "c:\Users\ahmed\OneDrive\Desktop\Graduation_project\venv312\Lib\site-packages\starlette\middleware\base.py", line 186, in __call__
  |     async with anyio.create_task_group() as task_group:
  |   File "c:\Users\ahmed\OneDrive\Desktop\Graduation_project\venv312\Lib\site-packages\anyio\_backends\_asyncio.py", line 763, in __aexit__
  |     raise BaseExceptionGroup(
  | ExceptionGroup: unhandled errors in a TaskGroup (1 sub-exception)
  +-+---------------- 1 ----------------
    | Traceback (most recent call last):
    |   File "c:\Users\ahmed\OneDrive\Desktop\Graduation_project\venv312\Lib\site-packages\starlette\middleware\errors.py", line 165, in __call__
    |     await self.app(scope, receive, _send)
    |   File "c:\Users\ahmed\OneDrive\Desktop\Graduation_project\venv312\Lib\site-packages\starlette\middleware\base.py", line 185, in __call__
    |     with collapse_excgroups():
    |   File "C:\Users\ahmed\AppData\Local\Programs\Python\Python312\Lib\contextlib.py", line 158, in __exit__
    |     self.gen.throw(value)
    |   File "c:\Users\ahmed\OneDrive\Desktop\Graduation_project\venv312\Lib\site-packages\starlette\_utils.py", line 82, in collapse_excgroups
    |     raise exc
    |   File "c:\Users\ahmed\OneDrive\Desktop\Graduation_project\venv312\Lib\site-packages\starlette\middleware\base.py", line 187, in __call__
    |     response = await self.dispatch_func(request, call_next)
    |                ^^^^^^^^^^^^^^^^^^^^^^^^^^^^^^^^^^^^^^^^^^^^
    |   File "C:\Users\ahmed\OneDrive\Desktop\Graduation_project\src\main.py", line 115, in add_security_headers
    |     for key, value in SecurityHeaders.get_security_headers().items():
    |                       ^^^^^^^^^^^^^^^^^^^^^^^^^^^^^^^^^^^^
    | AttributeError: type object 'SecurityHeaders' has no attribute 'get_security_headers'
    +------------------------------------

During handling of the above exception, another exception occurred:

Traceback (most recent call last):
  File "c:\Users\ahmed\OneDrive\Desktop\Graduation_project\venv312\Lib\site-packages\starlette\middleware\errors.py", line 165, in __call__
    await self.app(scope, receive, _send)
  File "c:\Users\ahmed\OneDrive\Desktop\Graduation_project\venv312\Lib\site-packages\starlette\middleware\base.py", line 185, in __call__
    with collapse_excgroups():
  File "C:\Users\ahmed\AppData\Local\Programs\Python\Python312\Lib\contextlib.py", line 158, in __exit__
    self.gen.throw(value)
  File "c:\Users\ahmed\OneDrive\Desktop\Graduation_project\venv312\Lib\site-packages\starlette\_utils.py", line 82, in collapse_excgroups
    raise exc
  File "c:\Users\ahmed\OneDrive\Desktop\Graduation_project\venv312\Lib\site-packages\starlette\middleware\base.py", line 187, in __call__
    response = await self.dispatch_func(request, call_next)
               ^^^^^^^^^^^^^^^^^^^^^^^^^^^^^^^^^^^^^^^^^^^^
  File "C:\Users\ahmed\OneDrive\Desktop\Graduation_project\src\main.py", line 115, in add_security_headers
    for key, value in SecurityHeaders.get_security_headers().items():
                      ^^^^^^^^^^^^^^^^^^^^^^^^^^^^^^^^^^^^
AttributeError: type object 'SecurityHeaders' has no attribute 'get_security_headers'
2024-12-01 11:53:56,311 - src.main - ERROR - Unhandled error: type object 'SecurityHeaders' has no attribute 'get_security_headers' - [C:\Users\ahmed\OneDrive\Desktop\Graduation_project\src\main.py:95]
  + Exception Group Traceback (most recent call last):
  |   File "c:\Users\ahmed\OneDrive\Desktop\Graduation_project\venv312\Lib\site-packages\starlette\_utils.py", line 76, in collapse_excgroups
  |     yield
  |   File "c:\Users\ahmed\OneDrive\Desktop\Graduation_project\venv312\Lib\site-packages\starlette\middleware\base.py", line 186, in __call__
  |     async with anyio.create_task_group() as task_group:
  |   File "c:\Users\ahmed\OneDrive\Desktop\Graduation_project\venv312\Lib\site-packages\anyio\_backends\_asyncio.py", line 763, in __aexit__
  |     raise BaseExceptionGroup(
  | ExceptionGroup: unhandled errors in a TaskGroup (1 sub-exception)
  +-+---------------- 1 ----------------
    | Traceback (most recent call last):
    |   File "c:\Users\ahmed\OneDrive\Desktop\Graduation_project\venv312\Lib\site-packages\starlette\middleware\errors.py", line 165, in __call__
    |     await self.app(scope, receive, _send)
    |   File "c:\Users\ahmed\OneDrive\Desktop\Graduation_project\venv312\Lib\site-packages\starlette\middleware\base.py", line 185, in __call__
    |     with collapse_excgroups():
    |   File "C:\Users\ahmed\AppData\Local\Programs\Python\Python312\Lib\contextlib.py", line 158, in __exit__
    |     self.gen.throw(value)
    |   File "c:\Users\ahmed\OneDrive\Desktop\Graduation_project\venv312\Lib\site-packages\starlette\_utils.py", line 82, in collapse_excgroups
    |     raise exc
    |   File "c:\Users\ahmed\OneDrive\Desktop\Graduation_project\venv312\Lib\site-packages\starlette\middleware\base.py", line 187, in __call__
    |     response = await self.dispatch_func(request, call_next)
    |                ^^^^^^^^^^^^^^^^^^^^^^^^^^^^^^^^^^^^^^^^^^^^
    |   File "C:\Users\ahmed\OneDrive\Desktop\Graduation_project\src\main.py", line 115, in add_security_headers
    |     for key, value in SecurityHeaders.get_security_headers().items():
    |                       ^^^^^^^^^^^^^^^^^^^^^^^^^^^^^^^^^^^^
    | AttributeError: type object 'SecurityHeaders' has no attribute 'get_security_headers'
    +------------------------------------

During handling of the above exception, another exception occurred:

Traceback (most recent call last):
  File "c:\Users\ahmed\OneDrive\Desktop\Graduation_project\venv312\Lib\site-packages\starlette\middleware\errors.py", line 165, in __call__
    await self.app(scope, receive, _send)
  File "c:\Users\ahmed\OneDrive\Desktop\Graduation_project\venv312\Lib\site-packages\starlette\middleware\base.py", line 185, in __call__
    with collapse_excgroups():
  File "C:\Users\ahmed\AppData\Local\Programs\Python\Python312\Lib\contextlib.py", line 158, in __exit__
    self.gen.throw(value)
  File "c:\Users\ahmed\OneDrive\Desktop\Graduation_project\venv312\Lib\site-packages\starlette\_utils.py", line 82, in collapse_excgroups
    raise exc
  File "c:\Users\ahmed\OneDrive\Desktop\Graduation_project\venv312\Lib\site-packages\starlette\middleware\base.py", line 187, in __call__
    response = await self.dispatch_func(request, call_next)
               ^^^^^^^^^^^^^^^^^^^^^^^^^^^^^^^^^^^^^^^^^^^^
  File "C:\Users\ahmed\OneDrive\Desktop\Graduation_project\src\main.py", line 115, in add_security_headers
    for key, value in SecurityHeaders.get_security_headers().items():
                      ^^^^^^^^^^^^^^^^^^^^^^^^^^^^^^^^^^^^
AttributeError: type object 'SecurityHeaders' has no attribute 'get_security_headers'
2024-12-01 11:53:57,002 - src.main - ERROR - Unhandled error: type object 'SecurityHeaders' has no attribute 'get_security_headers' - [C:\Users\ahmed\OneDrive\Desktop\Graduation_project\src\main.py:95]
  + Exception Group Traceback (most recent call last):
  |   File "c:\Users\ahmed\OneDrive\Desktop\Graduation_project\venv312\Lib\site-packages\starlette\_utils.py", line 76, in collapse_excgroups
  |     yield
  |   File "c:\Users\ahmed\OneDrive\Desktop\Graduation_project\venv312\Lib\site-packages\starlette\middleware\base.py", line 186, in __call__
  |     async with anyio.create_task_group() as task_group:
  |   File "c:\Users\ahmed\OneDrive\Desktop\Graduation_project\venv312\Lib\site-packages\anyio\_backends\_asyncio.py", line 763, in __aexit__
  |     raise BaseExceptionGroup(
  | ExceptionGroup: unhandled errors in a TaskGroup (1 sub-exception)
  +-+---------------- 1 ----------------
    | Traceback (most recent call last):
    |   File "c:\Users\ahmed\OneDrive\Desktop\Graduation_project\venv312\Lib\site-packages\starlette\middleware\errors.py", line 165, in __call__
    |     await self.app(scope, receive, _send)
    |   File "c:\Users\ahmed\OneDrive\Desktop\Graduation_project\venv312\Lib\site-packages\starlette\middleware\base.py", line 185, in __call__
    |     with collapse_excgroups():
    |   File "C:\Users\ahmed\AppData\Local\Programs\Python\Python312\Lib\contextlib.py", line 158, in __exit__
    |     self.gen.throw(value)
    |   File "c:\Users\ahmed\OneDrive\Desktop\Graduation_project\venv312\Lib\site-packages\starlette\_utils.py", line 82, in collapse_excgroups
    |     raise exc
    |   File "c:\Users\ahmed\OneDrive\Desktop\Graduation_project\venv312\Lib\site-packages\starlette\middleware\base.py", line 187, in __call__
    |     response = await self.dispatch_func(request, call_next)
    |                ^^^^^^^^^^^^^^^^^^^^^^^^^^^^^^^^^^^^^^^^^^^^
    |   File "C:\Users\ahmed\OneDrive\Desktop\Graduation_project\src\main.py", line 115, in add_security_headers
    |     for key, value in SecurityHeaders.get_security_headers().items():
    |                       ^^^^^^^^^^^^^^^^^^^^^^^^^^^^^^^^^^^^
    | AttributeError: type object 'SecurityHeaders' has no attribute 'get_security_headers'
    +------------------------------------

During handling of the above exception, another exception occurred:

Traceback (most recent call last):
  File "c:\Users\ahmed\OneDrive\Desktop\Graduation_project\venv312\Lib\site-packages\starlette\middleware\errors.py", line 165, in __call__
    await self.app(scope, receive, _send)
  File "c:\Users\ahmed\OneDrive\Desktop\Graduation_project\venv312\Lib\site-packages\starlette\middleware\base.py", line 185, in __call__
    with collapse_excgroups():
  File "C:\Users\ahmed\AppData\Local\Programs\Python\Python312\Lib\contextlib.py", line 158, in __exit__
    self.gen.throw(value)
  File "c:\Users\ahmed\OneDrive\Desktop\Graduation_project\venv312\Lib\site-packages\starlette\_utils.py", line 82, in collapse_excgroups
    raise exc
  File "c:\Users\ahmed\OneDrive\Desktop\Graduation_project\venv312\Lib\site-packages\starlette\middleware\base.py", line 187, in __call__
    response = await self.dispatch_func(request, call_next)
               ^^^^^^^^^^^^^^^^^^^^^^^^^^^^^^^^^^^^^^^^^^^^
  File "C:\Users\ahmed\OneDrive\Desktop\Graduation_project\src\main.py", line 115, in add_security_headers
    for key, value in SecurityHeaders.get_security_headers().items():
                      ^^^^^^^^^^^^^^^^^^^^^^^^^^^^^^^^^^^^
AttributeError: type object 'SecurityHeaders' has no attribute 'get_security_headers'
2024-12-01 11:53:57,626 - src.main - ERROR - Unhandled error: type object 'SecurityHeaders' has no attribute 'get_security_headers' - [C:\Users\ahmed\OneDrive\Desktop\Graduation_project\src\main.py:95]
  + Exception Group Traceback (most recent call last):
  |   File "c:\Users\ahmed\OneDrive\Desktop\Graduation_project\venv312\Lib\site-packages\starlette\_utils.py", line 76, in collapse_excgroups
  |     yield
  |   File "c:\Users\ahmed\OneDrive\Desktop\Graduation_project\venv312\Lib\site-packages\starlette\middleware\base.py", line 186, in __call__
  |     async with anyio.create_task_group() as task_group:
  |   File "c:\Users\ahmed\OneDrive\Desktop\Graduation_project\venv312\Lib\site-packages\anyio\_backends\_asyncio.py", line 763, in __aexit__
  |     raise BaseExceptionGroup(
  | ExceptionGroup: unhandled errors in a TaskGroup (1 sub-exception)
  +-+---------------- 1 ----------------
    | Traceback (most recent call last):
    |   File "c:\Users\ahmed\OneDrive\Desktop\Graduation_project\venv312\Lib\site-packages\starlette\middleware\errors.py", line 165, in __call__
    |     await self.app(scope, receive, _send)
    |   File "c:\Users\ahmed\OneDrive\Desktop\Graduation_project\venv312\Lib\site-packages\starlette\middleware\base.py", line 185, in __call__
    |     with collapse_excgroups():
    |   File "C:\Users\ahmed\AppData\Local\Programs\Python\Python312\Lib\contextlib.py", line 158, in __exit__
    |     self.gen.throw(value)
    |   File "c:\Users\ahmed\OneDrive\Desktop\Graduation_project\venv312\Lib\site-packages\starlette\_utils.py", line 82, in collapse_excgroups
    |     raise exc
    |   File "c:\Users\ahmed\OneDrive\Desktop\Graduation_project\venv312\Lib\site-packages\starlette\middleware\base.py", line 187, in __call__
    |     response = await self.dispatch_func(request, call_next)
    |                ^^^^^^^^^^^^^^^^^^^^^^^^^^^^^^^^^^^^^^^^^^^^
    |   File "C:\Users\ahmed\OneDrive\Desktop\Graduation_project\src\main.py", line 115, in add_security_headers
    |     for key, value in SecurityHeaders.get_security_headers().items():
    |                       ^^^^^^^^^^^^^^^^^^^^^^^^^^^^^^^^^^^^
    | AttributeError: type object 'SecurityHeaders' has no attribute 'get_security_headers'
    +------------------------------------

During handling of the above exception, another exception occurred:

Traceback (most recent call last):
  File "c:\Users\ahmed\OneDrive\Desktop\Graduation_project\venv312\Lib\site-packages\starlette\middleware\errors.py", line 165, in __call__
    await self.app(scope, receive, _send)
  File "c:\Users\ahmed\OneDrive\Desktop\Graduation_project\venv312\Lib\site-packages\starlette\middleware\base.py", line 185, in __call__
    with collapse_excgroups():
  File "C:\Users\ahmed\AppData\Local\Programs\Python\Python312\Lib\contextlib.py", line 158, in __exit__
    self.gen.throw(value)
  File "c:\Users\ahmed\OneDrive\Desktop\Graduation_project\venv312\Lib\site-packages\starlette\_utils.py", line 82, in collapse_excgroups
    raise exc
  File "c:\Users\ahmed\OneDrive\Desktop\Graduation_project\venv312\Lib\site-packages\starlette\middleware\base.py", line 187, in __call__
    response = await self.dispatch_func(request, call_next)
               ^^^^^^^^^^^^^^^^^^^^^^^^^^^^^^^^^^^^^^^^^^^^
  File "C:\Users\ahmed\OneDrive\Desktop\Graduation_project\src\main.py", line 115, in add_security_headers
    for key, value in SecurityHeaders.get_security_headers().items():
                      ^^^^^^^^^^^^^^^^^^^^^^^^^^^^^^^^^^^^
AttributeError: type object 'SecurityHeaders' has no attribute 'get_security_headers'
2024-12-01 11:53:58,308 - src.main - ERROR - Unhandled error: type object 'SecurityHeaders' has no attribute 'get_security_headers' - [C:\Users\ahmed\OneDrive\Desktop\Graduation_project\src\main.py:95]
  + Exception Group Traceback (most recent call last):
  |   File "c:\Users\ahmed\OneDrive\Desktop\Graduation_project\venv312\Lib\site-packages\starlette\_utils.py", line 76, in collapse_excgroups
  |     yield
  |   File "c:\Users\ahmed\OneDrive\Desktop\Graduation_project\venv312\Lib\site-packages\starlette\middleware\base.py", line 186, in __call__
  |     async with anyio.create_task_group() as task_group:
  |   File "c:\Users\ahmed\OneDrive\Desktop\Graduation_project\venv312\Lib\site-packages\anyio\_backends\_asyncio.py", line 763, in __aexit__
  |     raise BaseExceptionGroup(
  | ExceptionGroup: unhandled errors in a TaskGroup (1 sub-exception)
  +-+---------------- 1 ----------------
    | Traceback (most recent call last):
    |   File "c:\Users\ahmed\OneDrive\Desktop\Graduation_project\venv312\Lib\site-packages\starlette\middleware\errors.py", line 165, in __call__
    |     await self.app(scope, receive, _send)
    |   File "c:\Users\ahmed\OneDrive\Desktop\Graduation_project\venv312\Lib\site-packages\starlette\middleware\base.py", line 185, in __call__
    |     with collapse_excgroups():
    |   File "C:\Users\ahmed\AppData\Local\Programs\Python\Python312\Lib\contextlib.py", line 158, in __exit__
    |     self.gen.throw(value)
    |   File "c:\Users\ahmed\OneDrive\Desktop\Graduation_project\venv312\Lib\site-packages\starlette\_utils.py", line 82, in collapse_excgroups
    |     raise exc
    |   File "c:\Users\ahmed\OneDrive\Desktop\Graduation_project\venv312\Lib\site-packages\starlette\middleware\base.py", line 187, in __call__
    |     response = await self.dispatch_func(request, call_next)
    |                ^^^^^^^^^^^^^^^^^^^^^^^^^^^^^^^^^^^^^^^^^^^^
    |   File "C:\Users\ahmed\OneDrive\Desktop\Graduation_project\src\main.py", line 115, in add_security_headers
    |     for key, value in SecurityHeaders.get_security_headers().items():
    |                       ^^^^^^^^^^^^^^^^^^^^^^^^^^^^^^^^^^^^
    | AttributeError: type object 'SecurityHeaders' has no attribute 'get_security_headers'
    +------------------------------------

During handling of the above exception, another exception occurred:

Traceback (most recent call last):
  File "c:\Users\ahmed\OneDrive\Desktop\Graduation_project\venv312\Lib\site-packages\starlette\middleware\errors.py", line 165, in __call__
    await self.app(scope, receive, _send)
  File "c:\Users\ahmed\OneDrive\Desktop\Graduation_project\venv312\Lib\site-packages\starlette\middleware\base.py", line 185, in __call__
    with collapse_excgroups():
  File "C:\Users\ahmed\AppData\Local\Programs\Python\Python312\Lib\contextlib.py", line 158, in __exit__
    self.gen.throw(value)
  File "c:\Users\ahmed\OneDrive\Desktop\Graduation_project\venv312\Lib\site-packages\starlette\_utils.py", line 82, in collapse_excgroups
    raise exc
  File "c:\Users\ahmed\OneDrive\Desktop\Graduation_project\venv312\Lib\site-packages\starlette\middleware\base.py", line 187, in __call__
    response = await self.dispatch_func(request, call_next)
               ^^^^^^^^^^^^^^^^^^^^^^^^^^^^^^^^^^^^^^^^^^^^
  File "C:\Users\ahmed\OneDrive\Desktop\Graduation_project\src\main.py", line 115, in add_security_headers
    for key, value in SecurityHeaders.get_security_headers().items():
                      ^^^^^^^^^^^^^^^^^^^^^^^^^^^^^^^^^^^^
AttributeError: type object 'SecurityHeaders' has no attribute 'get_security_headers'
2024-12-01 11:53:58,991 - src.main - ERROR - Unhandled error: type object 'SecurityHeaders' has no attribute 'get_security_headers' - [C:\Users\ahmed\OneDrive\Desktop\Graduation_project\src\main.py:95]
  + Exception Group Traceback (most recent call last):
  |   File "c:\Users\ahmed\OneDrive\Desktop\Graduation_project\venv312\Lib\site-packages\starlette\_utils.py", line 76, in collapse_excgroups
  |     yield
  |   File "c:\Users\ahmed\OneDrive\Desktop\Graduation_project\venv312\Lib\site-packages\starlette\middleware\base.py", line 186, in __call__
  |     async with anyio.create_task_group() as task_group:
  |   File "c:\Users\ahmed\OneDrive\Desktop\Graduation_project\venv312\Lib\site-packages\anyio\_backends\_asyncio.py", line 763, in __aexit__
  |     raise BaseExceptionGroup(
  | ExceptionGroup: unhandled errors in a TaskGroup (1 sub-exception)
  +-+---------------- 1 ----------------
    | Traceback (most recent call last):
    |   File "c:\Users\ahmed\OneDrive\Desktop\Graduation_project\venv312\Lib\site-packages\starlette\middleware\errors.py", line 165, in __call__
    |     await self.app(scope, receive, _send)
    |   File "c:\Users\ahmed\OneDrive\Desktop\Graduation_project\venv312\Lib\site-packages\starlette\middleware\base.py", line 185, in __call__
    |     with collapse_excgroups():
    |   File "C:\Users\ahmed\AppData\Local\Programs\Python\Python312\Lib\contextlib.py", line 158, in __exit__
    |     self.gen.throw(value)
    |   File "c:\Users\ahmed\OneDrive\Desktop\Graduation_project\venv312\Lib\site-packages\starlette\_utils.py", line 82, in collapse_excgroups
    |     raise exc
    |   File "c:\Users\ahmed\OneDrive\Desktop\Graduation_project\venv312\Lib\site-packages\starlette\middleware\base.py", line 187, in __call__
    |     response = await self.dispatch_func(request, call_next)
    |                ^^^^^^^^^^^^^^^^^^^^^^^^^^^^^^^^^^^^^^^^^^^^
    |   File "C:\Users\ahmed\OneDrive\Desktop\Graduation_project\src\main.py", line 115, in add_security_headers
    |     for key, value in SecurityHeaders.get_security_headers().items():
    |                       ^^^^^^^^^^^^^^^^^^^^^^^^^^^^^^^^^^^^
    | AttributeError: type object 'SecurityHeaders' has no attribute 'get_security_headers'
    +------------------------------------

During handling of the above exception, another exception occurred:

Traceback (most recent call last):
  File "c:\Users\ahmed\OneDrive\Desktop\Graduation_project\venv312\Lib\site-packages\starlette\middleware\errors.py", line 165, in __call__
    await self.app(scope, receive, _send)
  File "c:\Users\ahmed\OneDrive\Desktop\Graduation_project\venv312\Lib\site-packages\starlette\middleware\base.py", line 185, in __call__
    with collapse_excgroups():
  File "C:\Users\ahmed\AppData\Local\Programs\Python\Python312\Lib\contextlib.py", line 158, in __exit__
    self.gen.throw(value)
  File "c:\Users\ahmed\OneDrive\Desktop\Graduation_project\venv312\Lib\site-packages\starlette\_utils.py", line 82, in collapse_excgroups
    raise exc
  File "c:\Users\ahmed\OneDrive\Desktop\Graduation_project\venv312\Lib\site-packages\starlette\middleware\base.py", line 187, in __call__
    response = await self.dispatch_func(request, call_next)
               ^^^^^^^^^^^^^^^^^^^^^^^^^^^^^^^^^^^^^^^^^^^^
  File "C:\Users\ahmed\OneDrive\Desktop\Graduation_project\src\main.py", line 115, in add_security_headers
    for key, value in SecurityHeaders.get_security_headers().items():
                      ^^^^^^^^^^^^^^^^^^^^^^^^^^^^^^^^^^^^
AttributeError: type object 'SecurityHeaders' has no attribute 'get_security_headers'
2024-12-01 11:53:59,784 - src.main - ERROR - Unhandled error: type object 'SecurityHeaders' has no attribute 'get_security_headers' - [C:\Users\ahmed\OneDrive\Desktop\Graduation_project\src\main.py:95]
  + Exception Group Traceback (most recent call last):
  |   File "c:\Users\ahmed\OneDrive\Desktop\Graduation_project\venv312\Lib\site-packages\starlette\_utils.py", line 76, in collapse_excgroups
  |     yield
  |   File "c:\Users\ahmed\OneDrive\Desktop\Graduation_project\venv312\Lib\site-packages\starlette\middleware\base.py", line 186, in __call__
  |     async with anyio.create_task_group() as task_group:
  |   File "c:\Users\ahmed\OneDrive\Desktop\Graduation_project\venv312\Lib\site-packages\anyio\_backends\_asyncio.py", line 763, in __aexit__
  |     raise BaseExceptionGroup(
  | ExceptionGroup: unhandled errors in a TaskGroup (1 sub-exception)
  +-+---------------- 1 ----------------
    | Traceback (most recent call last):
    |   File "c:\Users\ahmed\OneDrive\Desktop\Graduation_project\venv312\Lib\site-packages\starlette\middleware\errors.py", line 165, in __call__
    |     await self.app(scope, receive, _send)
    |   File "c:\Users\ahmed\OneDrive\Desktop\Graduation_project\venv312\Lib\site-packages\starlette\middleware\base.py", line 185, in __call__
    |     with collapse_excgroups():
    |   File "C:\Users\ahmed\AppData\Local\Programs\Python\Python312\Lib\contextlib.py", line 158, in __exit__
    |     self.gen.throw(value)
    |   File "c:\Users\ahmed\OneDrive\Desktop\Graduation_project\venv312\Lib\site-packages\starlette\_utils.py", line 82, in collapse_excgroups
    |     raise exc
    |   File "c:\Users\ahmed\OneDrive\Desktop\Graduation_project\venv312\Lib\site-packages\starlette\middleware\base.py", line 187, in __call__
    |     response = await self.dispatch_func(request, call_next)
    |                ^^^^^^^^^^^^^^^^^^^^^^^^^^^^^^^^^^^^^^^^^^^^
    |   File "C:\Users\ahmed\OneDrive\Desktop\Graduation_project\src\main.py", line 115, in add_security_headers
    |     for key, value in SecurityHeaders.get_security_headers().items():
    |                       ^^^^^^^^^^^^^^^^^^^^^^^^^^^^^^^^^^^^
    | AttributeError: type object 'SecurityHeaders' has no attribute 'get_security_headers'
    +------------------------------------

During handling of the above exception, another exception occurred:

Traceback (most recent call last):
  File "c:\Users\ahmed\OneDrive\Desktop\Graduation_project\venv312\Lib\site-packages\starlette\middleware\errors.py", line 165, in __call__
    await self.app(scope, receive, _send)
  File "c:\Users\ahmed\OneDrive\Desktop\Graduation_project\venv312\Lib\site-packages\starlette\middleware\base.py", line 185, in __call__
    with collapse_excgroups():
  File "C:\Users\ahmed\AppData\Local\Programs\Python\Python312\Lib\contextlib.py", line 158, in __exit__
    self.gen.throw(value)
  File "c:\Users\ahmed\OneDrive\Desktop\Graduation_project\venv312\Lib\site-packages\starlette\_utils.py", line 82, in collapse_excgroups
    raise exc
  File "c:\Users\ahmed\OneDrive\Desktop\Graduation_project\venv312\Lib\site-packages\starlette\middleware\base.py", line 187, in __call__
    response = await self.dispatch_func(request, call_next)
               ^^^^^^^^^^^^^^^^^^^^^^^^^^^^^^^^^^^^^^^^^^^^
  File "C:\Users\ahmed\OneDrive\Desktop\Graduation_project\src\main.py", line 115, in add_security_headers
    for key, value in SecurityHeaders.get_security_headers().items():
                      ^^^^^^^^^^^^^^^^^^^^^^^^^^^^^^^^^^^^
AttributeError: type object 'SecurityHeaders' has no attribute 'get_security_headers'
2024-12-01 11:54:00,702 - src.main - ERROR - Unhandled error: type object 'SecurityHeaders' has no attribute 'get_security_headers' - [C:\Users\ahmed\OneDrive\Desktop\Graduation_project\src\main.py:95]
  + Exception Group Traceback (most recent call last):
  |   File "c:\Users\ahmed\OneDrive\Desktop\Graduation_project\venv312\Lib\site-packages\starlette\_utils.py", line 76, in collapse_excgroups
  |     yield
  |   File "c:\Users\ahmed\OneDrive\Desktop\Graduation_project\venv312\Lib\site-packages\starlette\middleware\base.py", line 186, in __call__
  |     async with anyio.create_task_group() as task_group:
  |   File "c:\Users\ahmed\OneDrive\Desktop\Graduation_project\venv312\Lib\site-packages\anyio\_backends\_asyncio.py", line 763, in __aexit__
  |     raise BaseExceptionGroup(
  | ExceptionGroup: unhandled errors in a TaskGroup (1 sub-exception)
  +-+---------------- 1 ----------------
    | Traceback (most recent call last):
    |   File "c:\Users\ahmed\OneDrive\Desktop\Graduation_project\venv312\Lib\site-packages\starlette\middleware\errors.py", line 165, in __call__
    |     await self.app(scope, receive, _send)
    |   File "c:\Users\ahmed\OneDrive\Desktop\Graduation_project\venv312\Lib\site-packages\starlette\middleware\base.py", line 185, in __call__
    |     with collapse_excgroups():
    |   File "C:\Users\ahmed\AppData\Local\Programs\Python\Python312\Lib\contextlib.py", line 158, in __exit__
    |     self.gen.throw(value)
    |   File "c:\Users\ahmed\OneDrive\Desktop\Graduation_project\venv312\Lib\site-packages\starlette\_utils.py", line 82, in collapse_excgroups
    |     raise exc
    |   File "c:\Users\ahmed\OneDrive\Desktop\Graduation_project\venv312\Lib\site-packages\starlette\middleware\base.py", line 187, in __call__
    |     response = await self.dispatch_func(request, call_next)
    |                ^^^^^^^^^^^^^^^^^^^^^^^^^^^^^^^^^^^^^^^^^^^^
    |   File "C:\Users\ahmed\OneDrive\Desktop\Graduation_project\src\main.py", line 115, in add_security_headers
    |     for key, value in SecurityHeaders.get_security_headers().items():
    |                       ^^^^^^^^^^^^^^^^^^^^^^^^^^^^^^^^^^^^
    | AttributeError: type object 'SecurityHeaders' has no attribute 'get_security_headers'
    +------------------------------------

During handling of the above exception, another exception occurred:

Traceback (most recent call last):
  File "c:\Users\ahmed\OneDrive\Desktop\Graduation_project\venv312\Lib\site-packages\starlette\middleware\errors.py", line 165, in __call__
    await self.app(scope, receive, _send)
  File "c:\Users\ahmed\OneDrive\Desktop\Graduation_project\venv312\Lib\site-packages\starlette\middleware\base.py", line 185, in __call__
    with collapse_excgroups():
  File "C:\Users\ahmed\AppData\Local\Programs\Python\Python312\Lib\contextlib.py", line 158, in __exit__
    self.gen.throw(value)
  File "c:\Users\ahmed\OneDrive\Desktop\Graduation_project\venv312\Lib\site-packages\starlette\_utils.py", line 82, in collapse_excgroups
    raise exc
  File "c:\Users\ahmed\OneDrive\Desktop\Graduation_project\venv312\Lib\site-packages\starlette\middleware\base.py", line 187, in __call__
    response = await self.dispatch_func(request, call_next)
               ^^^^^^^^^^^^^^^^^^^^^^^^^^^^^^^^^^^^^^^^^^^^
  File "C:\Users\ahmed\OneDrive\Desktop\Graduation_project\src\main.py", line 115, in add_security_headers
    for key, value in SecurityHeaders.get_security_headers().items():
                      ^^^^^^^^^^^^^^^^^^^^^^^^^^^^^^^^^^^^
AttributeError: type object 'SecurityHeaders' has no attribute 'get_security_headers'
2024-12-01 11:54:01,465 - src.main - ERROR - Unhandled error: type object 'SecurityHeaders' has no attribute 'get_security_headers' - [C:\Users\ahmed\OneDrive\Desktop\Graduation_project\src\main.py:95]
  + Exception Group Traceback (most recent call last):
  |   File "c:\Users\ahmed\OneDrive\Desktop\Graduation_project\venv312\Lib\site-packages\starlette\_utils.py", line 76, in collapse_excgroups
  |     yield
  |   File "c:\Users\ahmed\OneDrive\Desktop\Graduation_project\venv312\Lib\site-packages\starlette\middleware\base.py", line 186, in __call__
  |     async with anyio.create_task_group() as task_group:
  |   File "c:\Users\ahmed\OneDrive\Desktop\Graduation_project\venv312\Lib\site-packages\anyio\_backends\_asyncio.py", line 763, in __aexit__
  |     raise BaseExceptionGroup(
  | ExceptionGroup: unhandled errors in a TaskGroup (1 sub-exception)
  +-+---------------- 1 ----------------
    | Traceback (most recent call last):
    |   File "c:\Users\ahmed\OneDrive\Desktop\Graduation_project\venv312\Lib\site-packages\starlette\middleware\errors.py", line 165, in __call__
    |     await self.app(scope, receive, _send)
    |   File "c:\Users\ahmed\OneDrive\Desktop\Graduation_project\venv312\Lib\site-packages\starlette\middleware\base.py", line 185, in __call__
    |     with collapse_excgroups():
    |   File "C:\Users\ahmed\AppData\Local\Programs\Python\Python312\Lib\contextlib.py", line 158, in __exit__
    |     self.gen.throw(value)
    |   File "c:\Users\ahmed\OneDrive\Desktop\Graduation_project\venv312\Lib\site-packages\starlette\_utils.py", line 82, in collapse_excgroups
    |     raise exc
    |   File "c:\Users\ahmed\OneDrive\Desktop\Graduation_project\venv312\Lib\site-packages\starlette\middleware\base.py", line 187, in __call__
    |     response = await self.dispatch_func(request, call_next)
    |                ^^^^^^^^^^^^^^^^^^^^^^^^^^^^^^^^^^^^^^^^^^^^
    |   File "C:\Users\ahmed\OneDrive\Desktop\Graduation_project\src\main.py", line 115, in add_security_headers
    |     for key, value in SecurityHeaders.get_security_headers().items():
    |                       ^^^^^^^^^^^^^^^^^^^^^^^^^^^^^^^^^^^^
    | AttributeError: type object 'SecurityHeaders' has no attribute 'get_security_headers'
    +------------------------------------

During handling of the above exception, another exception occurred:

Traceback (most recent call last):
  File "c:\Users\ahmed\OneDrive\Desktop\Graduation_project\venv312\Lib\site-packages\starlette\middleware\errors.py", line 165, in __call__
    await self.app(scope, receive, _send)
  File "c:\Users\ahmed\OneDrive\Desktop\Graduation_project\venv312\Lib\site-packages\starlette\middleware\base.py", line 185, in __call__
    with collapse_excgroups():
  File "C:\Users\ahmed\AppData\Local\Programs\Python\Python312\Lib\contextlib.py", line 158, in __exit__
    self.gen.throw(value)
  File "c:\Users\ahmed\OneDrive\Desktop\Graduation_project\venv312\Lib\site-packages\starlette\_utils.py", line 82, in collapse_excgroups
    raise exc
  File "c:\Users\ahmed\OneDrive\Desktop\Graduation_project\venv312\Lib\site-packages\starlette\middleware\base.py", line 187, in __call__
    response = await self.dispatch_func(request, call_next)
               ^^^^^^^^^^^^^^^^^^^^^^^^^^^^^^^^^^^^^^^^^^^^
  File "C:\Users\ahmed\OneDrive\Desktop\Graduation_project\src\main.py", line 115, in add_security_headers
    for key, value in SecurityHeaders.get_security_headers().items():
                      ^^^^^^^^^^^^^^^^^^^^^^^^^^^^^^^^^^^^
AttributeError: type object 'SecurityHeaders' has no attribute 'get_security_headers'
2024-12-01 11:54:02,158 - src.main - ERROR - Unhandled error: type object 'SecurityHeaders' has no attribute 'get_security_headers' - [C:\Users\ahmed\OneDrive\Desktop\Graduation_project\src\main.py:95]
  + Exception Group Traceback (most recent call last):
  |   File "c:\Users\ahmed\OneDrive\Desktop\Graduation_project\venv312\Lib\site-packages\starlette\_utils.py", line 76, in collapse_excgroups
  |     yield
  |   File "c:\Users\ahmed\OneDrive\Desktop\Graduation_project\venv312\Lib\site-packages\starlette\middleware\base.py", line 186, in __call__
  |     async with anyio.create_task_group() as task_group:
  |   File "c:\Users\ahmed\OneDrive\Desktop\Graduation_project\venv312\Lib\site-packages\anyio\_backends\_asyncio.py", line 763, in __aexit__
  |     raise BaseExceptionGroup(
  | ExceptionGroup: unhandled errors in a TaskGroup (1 sub-exception)
  +-+---------------- 1 ----------------
    | Traceback (most recent call last):
    |   File "c:\Users\ahmed\OneDrive\Desktop\Graduation_project\venv312\Lib\site-packages\starlette\middleware\errors.py", line 165, in __call__
    |     await self.app(scope, receive, _send)
    |   File "c:\Users\ahmed\OneDrive\Desktop\Graduation_project\venv312\Lib\site-packages\starlette\middleware\base.py", line 185, in __call__
    |     with collapse_excgroups():
    |   File "C:\Users\ahmed\AppData\Local\Programs\Python\Python312\Lib\contextlib.py", line 158, in __exit__
    |     self.gen.throw(value)
    |   File "c:\Users\ahmed\OneDrive\Desktop\Graduation_project\venv312\Lib\site-packages\starlette\_utils.py", line 82, in collapse_excgroups
    |     raise exc
    |   File "c:\Users\ahmed\OneDrive\Desktop\Graduation_project\venv312\Lib\site-packages\starlette\middleware\base.py", line 187, in __call__
    |     response = await self.dispatch_func(request, call_next)
    |                ^^^^^^^^^^^^^^^^^^^^^^^^^^^^^^^^^^^^^^^^^^^^
    |   File "C:\Users\ahmed\OneDrive\Desktop\Graduation_project\src\main.py", line 115, in add_security_headers
    |     for key, value in SecurityHeaders.get_security_headers().items():
    |                       ^^^^^^^^^^^^^^^^^^^^^^^^^^^^^^^^^^^^
    | AttributeError: type object 'SecurityHeaders' has no attribute 'get_security_headers'
    +------------------------------------

During handling of the above exception, another exception occurred:

Traceback (most recent call last):
  File "c:\Users\ahmed\OneDrive\Desktop\Graduation_project\venv312\Lib\site-packages\starlette\middleware\errors.py", line 165, in __call__
    await self.app(scope, receive, _send)
  File "c:\Users\ahmed\OneDrive\Desktop\Graduation_project\venv312\Lib\site-packages\starlette\middleware\base.py", line 185, in __call__
    with collapse_excgroups():
  File "C:\Users\ahmed\AppData\Local\Programs\Python\Python312\Lib\contextlib.py", line 158, in __exit__
    self.gen.throw(value)
  File "c:\Users\ahmed\OneDrive\Desktop\Graduation_project\venv312\Lib\site-packages\starlette\_utils.py", line 82, in collapse_excgroups
    raise exc
  File "c:\Users\ahmed\OneDrive\Desktop\Graduation_project\venv312\Lib\site-packages\starlette\middleware\base.py", line 187, in __call__
    response = await self.dispatch_func(request, call_next)
               ^^^^^^^^^^^^^^^^^^^^^^^^^^^^^^^^^^^^^^^^^^^^
  File "C:\Users\ahmed\OneDrive\Desktop\Graduation_project\src\main.py", line 115, in add_security_headers
    for key, value in SecurityHeaders.get_security_headers().items():
                      ^^^^^^^^^^^^^^^^^^^^^^^^^^^^^^^^^^^^
AttributeError: type object 'SecurityHeaders' has no attribute 'get_security_headers'
2024-12-01 11:54:02,933 - src.main - ERROR - Unhandled error: type object 'SecurityHeaders' has no attribute 'get_security_headers' - [C:\Users\ahmed\OneDrive\Desktop\Graduation_project\src\main.py:95]
  + Exception Group Traceback (most recent call last):
  |   File "c:\Users\ahmed\OneDrive\Desktop\Graduation_project\venv312\Lib\site-packages\starlette\_utils.py", line 76, in collapse_excgroups
  |     yield
  |   File "c:\Users\ahmed\OneDrive\Desktop\Graduation_project\venv312\Lib\site-packages\starlette\middleware\base.py", line 186, in __call__
  |     async with anyio.create_task_group() as task_group:
  |   File "c:\Users\ahmed\OneDrive\Desktop\Graduation_project\venv312\Lib\site-packages\anyio\_backends\_asyncio.py", line 763, in __aexit__
  |     raise BaseExceptionGroup(
  | ExceptionGroup: unhandled errors in a TaskGroup (1 sub-exception)
  +-+---------------- 1 ----------------
    | Traceback (most recent call last):
    |   File "c:\Users\ahmed\OneDrive\Desktop\Graduation_project\venv312\Lib\site-packages\starlette\middleware\errors.py", line 165, in __call__
    |     await self.app(scope, receive, _send)
    |   File "c:\Users\ahmed\OneDrive\Desktop\Graduation_project\venv312\Lib\site-packages\starlette\middleware\base.py", line 185, in __call__
    |     with collapse_excgroups():
    |   File "C:\Users\ahmed\AppData\Local\Programs\Python\Python312\Lib\contextlib.py", line 158, in __exit__
    |     self.gen.throw(value)
    |   File "c:\Users\ahmed\OneDrive\Desktop\Graduation_project\venv312\Lib\site-packages\starlette\_utils.py", line 82, in collapse_excgroups
    |     raise exc
    |   File "c:\Users\ahmed\OneDrive\Desktop\Graduation_project\venv312\Lib\site-packages\starlette\middleware\base.py", line 187, in __call__
    |     response = await self.dispatch_func(request, call_next)
    |                ^^^^^^^^^^^^^^^^^^^^^^^^^^^^^^^^^^^^^^^^^^^^
    |   File "C:\Users\ahmed\OneDrive\Desktop\Graduation_project\src\main.py", line 115, in add_security_headers
    |     for key, value in SecurityHeaders.get_security_headers().items():
    |                       ^^^^^^^^^^^^^^^^^^^^^^^^^^^^^^^^^^^^
    | AttributeError: type object 'SecurityHeaders' has no attribute 'get_security_headers'
    +------------------------------------

During handling of the above exception, another exception occurred:

Traceback (most recent call last):
  File "c:\Users\ahmed\OneDrive\Desktop\Graduation_project\venv312\Lib\site-packages\starlette\middleware\errors.py", line 165, in __call__
    await self.app(scope, receive, _send)
  File "c:\Users\ahmed\OneDrive\Desktop\Graduation_project\venv312\Lib\site-packages\starlette\middleware\base.py", line 185, in __call__
    with collapse_excgroups():
  File "C:\Users\ahmed\AppData\Local\Programs\Python\Python312\Lib\contextlib.py", line 158, in __exit__
    self.gen.throw(value)
  File "c:\Users\ahmed\OneDrive\Desktop\Graduation_project\venv312\Lib\site-packages\starlette\_utils.py", line 82, in collapse_excgroups
    raise exc
  File "c:\Users\ahmed\OneDrive\Desktop\Graduation_project\venv312\Lib\site-packages\starlette\middleware\base.py", line 187, in __call__
    response = await self.dispatch_func(request, call_next)
               ^^^^^^^^^^^^^^^^^^^^^^^^^^^^^^^^^^^^^^^^^^^^
  File "C:\Users\ahmed\OneDrive\Desktop\Graduation_project\src\main.py", line 115, in add_security_headers
    for key, value in SecurityHeaders.get_security_headers().items():
                      ^^^^^^^^^^^^^^^^^^^^^^^^^^^^^^^^^^^^
AttributeError: type object 'SecurityHeaders' has no attribute 'get_security_headers'
2024-12-01 11:54:03,607 - src.main - ERROR - Unhandled error: type object 'SecurityHeaders' has no attribute 'get_security_headers' - [C:\Users\ahmed\OneDrive\Desktop\Graduation_project\src\main.py:95]
  + Exception Group Traceback (most recent call last):
  |   File "c:\Users\ahmed\OneDrive\Desktop\Graduation_project\venv312\Lib\site-packages\starlette\_utils.py", line 76, in collapse_excgroups
  |     yield
  |   File "c:\Users\ahmed\OneDrive\Desktop\Graduation_project\venv312\Lib\site-packages\starlette\middleware\base.py", line 186, in __call__
  |     async with anyio.create_task_group() as task_group:
  |   File "c:\Users\ahmed\OneDrive\Desktop\Graduation_project\venv312\Lib\site-packages\anyio\_backends\_asyncio.py", line 763, in __aexit__
  |     raise BaseExceptionGroup(
  | ExceptionGroup: unhandled errors in a TaskGroup (1 sub-exception)
  +-+---------------- 1 ----------------
    | Traceback (most recent call last):
    |   File "c:\Users\ahmed\OneDrive\Desktop\Graduation_project\venv312\Lib\site-packages\starlette\middleware\errors.py", line 165, in __call__
    |     await self.app(scope, receive, _send)
    |   File "c:\Users\ahmed\OneDrive\Desktop\Graduation_project\venv312\Lib\site-packages\starlette\middleware\base.py", line 185, in __call__
    |     with collapse_excgroups():
    |   File "C:\Users\ahmed\AppData\Local\Programs\Python\Python312\Lib\contextlib.py", line 158, in __exit__
    |     self.gen.throw(value)
    |   File "c:\Users\ahmed\OneDrive\Desktop\Graduation_project\venv312\Lib\site-packages\starlette\_utils.py", line 82, in collapse_excgroups
    |     raise exc
    |   File "c:\Users\ahmed\OneDrive\Desktop\Graduation_project\venv312\Lib\site-packages\starlette\middleware\base.py", line 187, in __call__
    |     response = await self.dispatch_func(request, call_next)
    |                ^^^^^^^^^^^^^^^^^^^^^^^^^^^^^^^^^^^^^^^^^^^^
    |   File "C:\Users\ahmed\OneDrive\Desktop\Graduation_project\src\main.py", line 115, in add_security_headers
    |     for key, value in SecurityHeaders.get_security_headers().items():
    |                       ^^^^^^^^^^^^^^^^^^^^^^^^^^^^^^^^^^^^
    | AttributeError: type object 'SecurityHeaders' has no attribute 'get_security_headers'
    +------------------------------------

During handling of the above exception, another exception occurred:

Traceback (most recent call last):
  File "c:\Users\ahmed\OneDrive\Desktop\Graduation_project\venv312\Lib\site-packages\starlette\middleware\errors.py", line 165, in __call__
    await self.app(scope, receive, _send)
  File "c:\Users\ahmed\OneDrive\Desktop\Graduation_project\venv312\Lib\site-packages\starlette\middleware\base.py", line 185, in __call__
    with collapse_excgroups():
  File "C:\Users\ahmed\AppData\Local\Programs\Python\Python312\Lib\contextlib.py", line 158, in __exit__
    self.gen.throw(value)
  File "c:\Users\ahmed\OneDrive\Desktop\Graduation_project\venv312\Lib\site-packages\starlette\_utils.py", line 82, in collapse_excgroups
    raise exc
  File "c:\Users\ahmed\OneDrive\Desktop\Graduation_project\venv312\Lib\site-packages\starlette\middleware\base.py", line 187, in __call__
    response = await self.dispatch_func(request, call_next)
               ^^^^^^^^^^^^^^^^^^^^^^^^^^^^^^^^^^^^^^^^^^^^
  File "C:\Users\ahmed\OneDrive\Desktop\Graduation_project\src\main.py", line 115, in add_security_headers
    for key, value in SecurityHeaders.get_security_headers().items():
                      ^^^^^^^^^^^^^^^^^^^^^^^^^^^^^^^^^^^^
AttributeError: type object 'SecurityHeaders' has no attribute 'get_security_headers'
2024-12-01 11:54:04,297 - src.main - ERROR - Unhandled error: type object 'SecurityHeaders' has no attribute 'get_security_headers' - [C:\Users\ahmed\OneDrive\Desktop\Graduation_project\src\main.py:95]
  + Exception Group Traceback (most recent call last):
  |   File "c:\Users\ahmed\OneDrive\Desktop\Graduation_project\venv312\Lib\site-packages\starlette\_utils.py", line 76, in collapse_excgroups
  |     yield
  |   File "c:\Users\ahmed\OneDrive\Desktop\Graduation_project\venv312\Lib\site-packages\starlette\middleware\base.py", line 186, in __call__
  |     async with anyio.create_task_group() as task_group:
  |   File "c:\Users\ahmed\OneDrive\Desktop\Graduation_project\venv312\Lib\site-packages\anyio\_backends\_asyncio.py", line 763, in __aexit__
  |     raise BaseExceptionGroup(
  | ExceptionGroup: unhandled errors in a TaskGroup (1 sub-exception)
  +-+---------------- 1 ----------------
    | Traceback (most recent call last):
    |   File "c:\Users\ahmed\OneDrive\Desktop\Graduation_project\venv312\Lib\site-packages\starlette\middleware\errors.py", line 165, in __call__
    |     await self.app(scope, receive, _send)
    |   File "c:\Users\ahmed\OneDrive\Desktop\Graduation_project\venv312\Lib\site-packages\starlette\middleware\base.py", line 185, in __call__
    |     with collapse_excgroups():
    |   File "C:\Users\ahmed\AppData\Local\Programs\Python\Python312\Lib\contextlib.py", line 158, in __exit__
    |     self.gen.throw(value)
    |   File "c:\Users\ahmed\OneDrive\Desktop\Graduation_project\venv312\Lib\site-packages\starlette\_utils.py", line 82, in collapse_excgroups
    |     raise exc
    |   File "c:\Users\ahmed\OneDrive\Desktop\Graduation_project\venv312\Lib\site-packages\starlette\middleware\base.py", line 187, in __call__
    |     response = await self.dispatch_func(request, call_next)
    |                ^^^^^^^^^^^^^^^^^^^^^^^^^^^^^^^^^^^^^^^^^^^^
    |   File "C:\Users\ahmed\OneDrive\Desktop\Graduation_project\src\main.py", line 115, in add_security_headers
    |     for key, value in SecurityHeaders.get_security_headers().items():
    |                       ^^^^^^^^^^^^^^^^^^^^^^^^^^^^^^^^^^^^
    | AttributeError: type object 'SecurityHeaders' has no attribute 'get_security_headers'
    +------------------------------------

During handling of the above exception, another exception occurred:

Traceback (most recent call last):
  File "c:\Users\ahmed\OneDrive\Desktop\Graduation_project\venv312\Lib\site-packages\starlette\middleware\errors.py", line 165, in __call__
    await self.app(scope, receive, _send)
  File "c:\Users\ahmed\OneDrive\Desktop\Graduation_project\venv312\Lib\site-packages\starlette\middleware\base.py", line 185, in __call__
    with collapse_excgroups():
  File "C:\Users\ahmed\AppData\Local\Programs\Python\Python312\Lib\contextlib.py", line 158, in __exit__
    self.gen.throw(value)
  File "c:\Users\ahmed\OneDrive\Desktop\Graduation_project\venv312\Lib\site-packages\starlette\_utils.py", line 82, in collapse_excgroups
    raise exc
  File "c:\Users\ahmed\OneDrive\Desktop\Graduation_project\venv312\Lib\site-packages\starlette\middleware\base.py", line 187, in __call__
    response = await self.dispatch_func(request, call_next)
               ^^^^^^^^^^^^^^^^^^^^^^^^^^^^^^^^^^^^^^^^^^^^
  File "C:\Users\ahmed\OneDrive\Desktop\Graduation_project\src\main.py", line 115, in add_security_headers
    for key, value in SecurityHeaders.get_security_headers().items():
                      ^^^^^^^^^^^^^^^^^^^^^^^^^^^^^^^^^^^^
AttributeError: type object 'SecurityHeaders' has no attribute 'get_security_headers'
2024-12-01 11:54:04,968 - src.main - ERROR - Unhandled error: type object 'SecurityHeaders' has no attribute 'get_security_headers' - [C:\Users\ahmed\OneDrive\Desktop\Graduation_project\src\main.py:95]
  + Exception Group Traceback (most recent call last):
  |   File "c:\Users\ahmed\OneDrive\Desktop\Graduation_project\venv312\Lib\site-packages\starlette\_utils.py", line 76, in collapse_excgroups
  |     yield
  |   File "c:\Users\ahmed\OneDrive\Desktop\Graduation_project\venv312\Lib\site-packages\starlette\middleware\base.py", line 186, in __call__
  |     async with anyio.create_task_group() as task_group:
  |   File "c:\Users\ahmed\OneDrive\Desktop\Graduation_project\venv312\Lib\site-packages\anyio\_backends\_asyncio.py", line 763, in __aexit__
  |     raise BaseExceptionGroup(
  | ExceptionGroup: unhandled errors in a TaskGroup (1 sub-exception)
  +-+---------------- 1 ----------------
    | Traceback (most recent call last):
    |   File "c:\Users\ahmed\OneDrive\Desktop\Graduation_project\venv312\Lib\site-packages\starlette\middleware\errors.py", line 165, in __call__
    |     await self.app(scope, receive, _send)
    |   File "c:\Users\ahmed\OneDrive\Desktop\Graduation_project\venv312\Lib\site-packages\starlette\middleware\base.py", line 185, in __call__
    |     with collapse_excgroups():
    |   File "C:\Users\ahmed\AppData\Local\Programs\Python\Python312\Lib\contextlib.py", line 158, in __exit__
    |     self.gen.throw(value)
    |   File "c:\Users\ahmed\OneDrive\Desktop\Graduation_project\venv312\Lib\site-packages\starlette\_utils.py", line 82, in collapse_excgroups
    |     raise exc
    |   File "c:\Users\ahmed\OneDrive\Desktop\Graduation_project\venv312\Lib\site-packages\starlette\middleware\base.py", line 187, in __call__
    |     response = await self.dispatch_func(request, call_next)
    |                ^^^^^^^^^^^^^^^^^^^^^^^^^^^^^^^^^^^^^^^^^^^^
    |   File "C:\Users\ahmed\OneDrive\Desktop\Graduation_project\src\main.py", line 115, in add_security_headers
    |     for key, value in SecurityHeaders.get_security_headers().items():
    |                       ^^^^^^^^^^^^^^^^^^^^^^^^^^^^^^^^^^^^
    | AttributeError: type object 'SecurityHeaders' has no attribute 'get_security_headers'
    +------------------------------------

During handling of the above exception, another exception occurred:

Traceback (most recent call last):
  File "c:\Users\ahmed\OneDrive\Desktop\Graduation_project\venv312\Lib\site-packages\starlette\middleware\errors.py", line 165, in __call__
    await self.app(scope, receive, _send)
  File "c:\Users\ahmed\OneDrive\Desktop\Graduation_project\venv312\Lib\site-packages\starlette\middleware\base.py", line 185, in __call__
    with collapse_excgroups():
  File "C:\Users\ahmed\AppData\Local\Programs\Python\Python312\Lib\contextlib.py", line 158, in __exit__
    self.gen.throw(value)
  File "c:\Users\ahmed\OneDrive\Desktop\Graduation_project\venv312\Lib\site-packages\starlette\_utils.py", line 82, in collapse_excgroups
    raise exc
  File "c:\Users\ahmed\OneDrive\Desktop\Graduation_project\venv312\Lib\site-packages\starlette\middleware\base.py", line 187, in __call__
    response = await self.dispatch_func(request, call_next)
               ^^^^^^^^^^^^^^^^^^^^^^^^^^^^^^^^^^^^^^^^^^^^
  File "C:\Users\ahmed\OneDrive\Desktop\Graduation_project\src\main.py", line 115, in add_security_headers
    for key, value in SecurityHeaders.get_security_headers().items():
                      ^^^^^^^^^^^^^^^^^^^^^^^^^^^^^^^^^^^^
AttributeError: type object 'SecurityHeaders' has no attribute 'get_security_headers'
2024-12-01 11:54:05,635 - src.main - ERROR - Unhandled error: type object 'SecurityHeaders' has no attribute 'get_security_headers' - [C:\Users\ahmed\OneDrive\Desktop\Graduation_project\src\main.py:95]
  + Exception Group Traceback (most recent call last):
  |   File "c:\Users\ahmed\OneDrive\Desktop\Graduation_project\venv312\Lib\site-packages\starlette\_utils.py", line 76, in collapse_excgroups
  |     yield
  |   File "c:\Users\ahmed\OneDrive\Desktop\Graduation_project\venv312\Lib\site-packages\starlette\middleware\base.py", line 186, in __call__
  |     async with anyio.create_task_group() as task_group:
  |   File "c:\Users\ahmed\OneDrive\Desktop\Graduation_project\venv312\Lib\site-packages\anyio\_backends\_asyncio.py", line 763, in __aexit__
  |     raise BaseExceptionGroup(
  | ExceptionGroup: unhandled errors in a TaskGroup (1 sub-exception)
  +-+---------------- 1 ----------------
    | Traceback (most recent call last):
    |   File "c:\Users\ahmed\OneDrive\Desktop\Graduation_project\venv312\Lib\site-packages\starlette\middleware\errors.py", line 165, in __call__
    |     await self.app(scope, receive, _send)
    |   File "c:\Users\ahmed\OneDrive\Desktop\Graduation_project\venv312\Lib\site-packages\starlette\middleware\base.py", line 185, in __call__
    |     with collapse_excgroups():
    |   File "C:\Users\ahmed\AppData\Local\Programs\Python\Python312\Lib\contextlib.py", line 158, in __exit__
    |     self.gen.throw(value)
    |   File "c:\Users\ahmed\OneDrive\Desktop\Graduation_project\venv312\Lib\site-packages\starlette\_utils.py", line 82, in collapse_excgroups
    |     raise exc
    |   File "c:\Users\ahmed\OneDrive\Desktop\Graduation_project\venv312\Lib\site-packages\starlette\middleware\base.py", line 187, in __call__
    |     response = await self.dispatch_func(request, call_next)
    |                ^^^^^^^^^^^^^^^^^^^^^^^^^^^^^^^^^^^^^^^^^^^^
    |   File "C:\Users\ahmed\OneDrive\Desktop\Graduation_project\src\main.py", line 115, in add_security_headers
    |     for key, value in SecurityHeaders.get_security_headers().items():
    |                       ^^^^^^^^^^^^^^^^^^^^^^^^^^^^^^^^^^^^
    | AttributeError: type object 'SecurityHeaders' has no attribute 'get_security_headers'
    +------------------------------------

During handling of the above exception, another exception occurred:

Traceback (most recent call last):
  File "c:\Users\ahmed\OneDrive\Desktop\Graduation_project\venv312\Lib\site-packages\starlette\middleware\errors.py", line 165, in __call__
    await self.app(scope, receive, _send)
  File "c:\Users\ahmed\OneDrive\Desktop\Graduation_project\venv312\Lib\site-packages\starlette\middleware\base.py", line 185, in __call__
    with collapse_excgroups():
  File "C:\Users\ahmed\AppData\Local\Programs\Python\Python312\Lib\contextlib.py", line 158, in __exit__
    self.gen.throw(value)
  File "c:\Users\ahmed\OneDrive\Desktop\Graduation_project\venv312\Lib\site-packages\starlette\_utils.py", line 82, in collapse_excgroups
    raise exc
  File "c:\Users\ahmed\OneDrive\Desktop\Graduation_project\venv312\Lib\site-packages\starlette\middleware\base.py", line 187, in __call__
    response = await self.dispatch_func(request, call_next)
               ^^^^^^^^^^^^^^^^^^^^^^^^^^^^^^^^^^^^^^^^^^^^
  File "C:\Users\ahmed\OneDrive\Desktop\Graduation_project\src\main.py", line 115, in add_security_headers
    for key, value in SecurityHeaders.get_security_headers().items():
                      ^^^^^^^^^^^^^^^^^^^^^^^^^^^^^^^^^^^^
AttributeError: type object 'SecurityHeaders' has no attribute 'get_security_headers'
2024-12-01 11:54:06,301 - src.main - ERROR - Unhandled error: type object 'SecurityHeaders' has no attribute 'get_security_headers' - [C:\Users\ahmed\OneDrive\Desktop\Graduation_project\src\main.py:95]
  + Exception Group Traceback (most recent call last):
  |   File "c:\Users\ahmed\OneDrive\Desktop\Graduation_project\venv312\Lib\site-packages\starlette\_utils.py", line 76, in collapse_excgroups
  |     yield
  |   File "c:\Users\ahmed\OneDrive\Desktop\Graduation_project\venv312\Lib\site-packages\starlette\middleware\base.py", line 186, in __call__
  |     async with anyio.create_task_group() as task_group:
  |   File "c:\Users\ahmed\OneDrive\Desktop\Graduation_project\venv312\Lib\site-packages\anyio\_backends\_asyncio.py", line 763, in __aexit__
  |     raise BaseExceptionGroup(
  | ExceptionGroup: unhandled errors in a TaskGroup (1 sub-exception)
  +-+---------------- 1 ----------------
    | Traceback (most recent call last):
    |   File "c:\Users\ahmed\OneDrive\Desktop\Graduation_project\venv312\Lib\site-packages\starlette\middleware\errors.py", line 165, in __call__
    |     await self.app(scope, receive, _send)
    |   File "c:\Users\ahmed\OneDrive\Desktop\Graduation_project\venv312\Lib\site-packages\starlette\middleware\base.py", line 185, in __call__
    |     with collapse_excgroups():
    |   File "C:\Users\ahmed\AppData\Local\Programs\Python\Python312\Lib\contextlib.py", line 158, in __exit__
    |     self.gen.throw(value)
    |   File "c:\Users\ahmed\OneDrive\Desktop\Graduation_project\venv312\Lib\site-packages\starlette\_utils.py", line 82, in collapse_excgroups
    |     raise exc
    |   File "c:\Users\ahmed\OneDrive\Desktop\Graduation_project\venv312\Lib\site-packages\starlette\middleware\base.py", line 187, in __call__
    |     response = await self.dispatch_func(request, call_next)
    |                ^^^^^^^^^^^^^^^^^^^^^^^^^^^^^^^^^^^^^^^^^^^^
    |   File "C:\Users\ahmed\OneDrive\Desktop\Graduation_project\src\main.py", line 115, in add_security_headers
    |     for key, value in SecurityHeaders.get_security_headers().items():
    |                       ^^^^^^^^^^^^^^^^^^^^^^^^^^^^^^^^^^^^
    | AttributeError: type object 'SecurityHeaders' has no attribute 'get_security_headers'
    +------------------------------------

During handling of the above exception, another exception occurred:

Traceback (most recent call last):
  File "c:\Users\ahmed\OneDrive\Desktop\Graduation_project\venv312\Lib\site-packages\starlette\middleware\errors.py", line 165, in __call__
    await self.app(scope, receive, _send)
  File "c:\Users\ahmed\OneDrive\Desktop\Graduation_project\venv312\Lib\site-packages\starlette\middleware\base.py", line 185, in __call__
    with collapse_excgroups():
  File "C:\Users\ahmed\AppData\Local\Programs\Python\Python312\Lib\contextlib.py", line 158, in __exit__
    self.gen.throw(value)
  File "c:\Users\ahmed\OneDrive\Desktop\Graduation_project\venv312\Lib\site-packages\starlette\_utils.py", line 82, in collapse_excgroups
    raise exc
  File "c:\Users\ahmed\OneDrive\Desktop\Graduation_project\venv312\Lib\site-packages\starlette\middleware\base.py", line 187, in __call__
    response = await self.dispatch_func(request, call_next)
               ^^^^^^^^^^^^^^^^^^^^^^^^^^^^^^^^^^^^^^^^^^^^
  File "C:\Users\ahmed\OneDrive\Desktop\Graduation_project\src\main.py", line 115, in add_security_headers
    for key, value in SecurityHeaders.get_security_headers().items():
                      ^^^^^^^^^^^^^^^^^^^^^^^^^^^^^^^^^^^^
AttributeError: type object 'SecurityHeaders' has no attribute 'get_security_headers'
2024-12-01 11:54:06,968 - src.main - ERROR - Unhandled error: type object 'SecurityHeaders' has no attribute 'get_security_headers' - [C:\Users\ahmed\OneDrive\Desktop\Graduation_project\src\main.py:95]
  + Exception Group Traceback (most recent call last):
  |   File "c:\Users\ahmed\OneDrive\Desktop\Graduation_project\venv312\Lib\site-packages\starlette\_utils.py", line 76, in collapse_excgroups
  |     yield
  |   File "c:\Users\ahmed\OneDrive\Desktop\Graduation_project\venv312\Lib\site-packages\starlette\middleware\base.py", line 186, in __call__
  |     async with anyio.create_task_group() as task_group:
  |   File "c:\Users\ahmed\OneDrive\Desktop\Graduation_project\venv312\Lib\site-packages\anyio\_backends\_asyncio.py", line 763, in __aexit__
  |     raise BaseExceptionGroup(
  | ExceptionGroup: unhandled errors in a TaskGroup (1 sub-exception)
  +-+---------------- 1 ----------------
    | Traceback (most recent call last):
    |   File "c:\Users\ahmed\OneDrive\Desktop\Graduation_project\venv312\Lib\site-packages\starlette\middleware\errors.py", line 165, in __call__
    |     await self.app(scope, receive, _send)
    |   File "c:\Users\ahmed\OneDrive\Desktop\Graduation_project\venv312\Lib\site-packages\starlette\middleware\base.py", line 185, in __call__
    |     with collapse_excgroups():
    |   File "C:\Users\ahmed\AppData\Local\Programs\Python\Python312\Lib\contextlib.py", line 158, in __exit__
    |     self.gen.throw(value)
    |   File "c:\Users\ahmed\OneDrive\Desktop\Graduation_project\venv312\Lib\site-packages\starlette\_utils.py", line 82, in collapse_excgroups
    |     raise exc
    |   File "c:\Users\ahmed\OneDrive\Desktop\Graduation_project\venv312\Lib\site-packages\starlette\middleware\base.py", line 187, in __call__
    |     response = await self.dispatch_func(request, call_next)
    |                ^^^^^^^^^^^^^^^^^^^^^^^^^^^^^^^^^^^^^^^^^^^^
    |   File "C:\Users\ahmed\OneDrive\Desktop\Graduation_project\src\main.py", line 115, in add_security_headers
    |     for key, value in SecurityHeaders.get_security_headers().items():
    |                       ^^^^^^^^^^^^^^^^^^^^^^^^^^^^^^^^^^^^
    | AttributeError: type object 'SecurityHeaders' has no attribute 'get_security_headers'
    +------------------------------------

During handling of the above exception, another exception occurred:

Traceback (most recent call last):
  File "c:\Users\ahmed\OneDrive\Desktop\Graduation_project\venv312\Lib\site-packages\starlette\middleware\errors.py", line 165, in __call__
    await self.app(scope, receive, _send)
  File "c:\Users\ahmed\OneDrive\Desktop\Graduation_project\venv312\Lib\site-packages\starlette\middleware\base.py", line 185, in __call__
    with collapse_excgroups():
  File "C:\Users\ahmed\AppData\Local\Programs\Python\Python312\Lib\contextlib.py", line 158, in __exit__
    self.gen.throw(value)
  File "c:\Users\ahmed\OneDrive\Desktop\Graduation_project\venv312\Lib\site-packages\starlette\_utils.py", line 82, in collapse_excgroups
    raise exc
  File "c:\Users\ahmed\OneDrive\Desktop\Graduation_project\venv312\Lib\site-packages\starlette\middleware\base.py", line 187, in __call__
    response = await self.dispatch_func(request, call_next)
               ^^^^^^^^^^^^^^^^^^^^^^^^^^^^^^^^^^^^^^^^^^^^
  File "C:\Users\ahmed\OneDrive\Desktop\Graduation_project\src\main.py", line 115, in add_security_headers
    for key, value in SecurityHeaders.get_security_headers().items():
                      ^^^^^^^^^^^^^^^^^^^^^^^^^^^^^^^^^^^^
AttributeError: type object 'SecurityHeaders' has no attribute 'get_security_headers'
2024-12-01 11:54:07,699 - src.main - ERROR - Unhandled error: type object 'SecurityHeaders' has no attribute 'get_security_headers' - [C:\Users\ahmed\OneDrive\Desktop\Graduation_project\src\main.py:95]
  + Exception Group Traceback (most recent call last):
  |   File "c:\Users\ahmed\OneDrive\Desktop\Graduation_project\venv312\Lib\site-packages\starlette\_utils.py", line 76, in collapse_excgroups
  |     yield
  |   File "c:\Users\ahmed\OneDrive\Desktop\Graduation_project\venv312\Lib\site-packages\starlette\middleware\base.py", line 186, in __call__
  |     async with anyio.create_task_group() as task_group:
  |   File "c:\Users\ahmed\OneDrive\Desktop\Graduation_project\venv312\Lib\site-packages\anyio\_backends\_asyncio.py", line 763, in __aexit__
  |     raise BaseExceptionGroup(
  | ExceptionGroup: unhandled errors in a TaskGroup (1 sub-exception)
  +-+---------------- 1 ----------------
    | Traceback (most recent call last):
    |   File "c:\Users\ahmed\OneDrive\Desktop\Graduation_project\venv312\Lib\site-packages\starlette\middleware\errors.py", line 165, in __call__
    |     await self.app(scope, receive, _send)
    |   File "c:\Users\ahmed\OneDrive\Desktop\Graduation_project\venv312\Lib\site-packages\starlette\middleware\base.py", line 185, in __call__
    |     with collapse_excgroups():
    |   File "C:\Users\ahmed\AppData\Local\Programs\Python\Python312\Lib\contextlib.py", line 158, in __exit__
    |     self.gen.throw(value)
    |   File "c:\Users\ahmed\OneDrive\Desktop\Graduation_project\venv312\Lib\site-packages\starlette\_utils.py", line 82, in collapse_excgroups
    |     raise exc
    |   File "c:\Users\ahmed\OneDrive\Desktop\Graduation_project\venv312\Lib\site-packages\starlette\middleware\base.py", line 187, in __call__
    |     response = await self.dispatch_func(request, call_next)
    |                ^^^^^^^^^^^^^^^^^^^^^^^^^^^^^^^^^^^^^^^^^^^^
    |   File "C:\Users\ahmed\OneDrive\Desktop\Graduation_project\src\main.py", line 115, in add_security_headers
    |     for key, value in SecurityHeaders.get_security_headers().items():
    |                       ^^^^^^^^^^^^^^^^^^^^^^^^^^^^^^^^^^^^
    | AttributeError: type object 'SecurityHeaders' has no attribute 'get_security_headers'
    +------------------------------------

During handling of the above exception, another exception occurred:

Traceback (most recent call last):
  File "c:\Users\ahmed\OneDrive\Desktop\Graduation_project\venv312\Lib\site-packages\starlette\middleware\errors.py", line 165, in __call__
    await self.app(scope, receive, _send)
  File "c:\Users\ahmed\OneDrive\Desktop\Graduation_project\venv312\Lib\site-packages\starlette\middleware\base.py", line 185, in __call__
    with collapse_excgroups():
  File "C:\Users\ahmed\AppData\Local\Programs\Python\Python312\Lib\contextlib.py", line 158, in __exit__
    self.gen.throw(value)
  File "c:\Users\ahmed\OneDrive\Desktop\Graduation_project\venv312\Lib\site-packages\starlette\_utils.py", line 82, in collapse_excgroups
    raise exc
  File "c:\Users\ahmed\OneDrive\Desktop\Graduation_project\venv312\Lib\site-packages\starlette\middleware\base.py", line 187, in __call__
    response = await self.dispatch_func(request, call_next)
               ^^^^^^^^^^^^^^^^^^^^^^^^^^^^^^^^^^^^^^^^^^^^
  File "C:\Users\ahmed\OneDrive\Desktop\Graduation_project\src\main.py", line 115, in add_security_headers
    for key, value in SecurityHeaders.get_security_headers().items():
                      ^^^^^^^^^^^^^^^^^^^^^^^^^^^^^^^^^^^^
AttributeError: type object 'SecurityHeaders' has no attribute 'get_security_headers'
2024-12-01 11:54:08,379 - src.main - ERROR - Unhandled error: type object 'SecurityHeaders' has no attribute 'get_security_headers' - [C:\Users\ahmed\OneDrive\Desktop\Graduation_project\src\main.py:95]
  + Exception Group Traceback (most recent call last):
  |   File "c:\Users\ahmed\OneDrive\Desktop\Graduation_project\venv312\Lib\site-packages\starlette\_utils.py", line 76, in collapse_excgroups
  |     yield
  |   File "c:\Users\ahmed\OneDrive\Desktop\Graduation_project\venv312\Lib\site-packages\starlette\middleware\base.py", line 186, in __call__
  |     async with anyio.create_task_group() as task_group:
  |   File "c:\Users\ahmed\OneDrive\Desktop\Graduation_project\venv312\Lib\site-packages\anyio\_backends\_asyncio.py", line 763, in __aexit__
  |     raise BaseExceptionGroup(
  | ExceptionGroup: unhandled errors in a TaskGroup (1 sub-exception)
  +-+---------------- 1 ----------------
    | Traceback (most recent call last):
    |   File "c:\Users\ahmed\OneDrive\Desktop\Graduation_project\venv312\Lib\site-packages\starlette\middleware\errors.py", line 165, in __call__
    |     await self.app(scope, receive, _send)
    |   File "c:\Users\ahmed\OneDrive\Desktop\Graduation_project\venv312\Lib\site-packages\starlette\middleware\base.py", line 185, in __call__
    |     with collapse_excgroups():
    |   File "C:\Users\ahmed\AppData\Local\Programs\Python\Python312\Lib\contextlib.py", line 158, in __exit__
    |     self.gen.throw(value)
    |   File "c:\Users\ahmed\OneDrive\Desktop\Graduation_project\venv312\Lib\site-packages\starlette\_utils.py", line 82, in collapse_excgroups
    |     raise exc
    |   File "c:\Users\ahmed\OneDrive\Desktop\Graduation_project\venv312\Lib\site-packages\starlette\middleware\base.py", line 187, in __call__
    |     response = await self.dispatch_func(request, call_next)
    |                ^^^^^^^^^^^^^^^^^^^^^^^^^^^^^^^^^^^^^^^^^^^^
    |   File "C:\Users\ahmed\OneDrive\Desktop\Graduation_project\src\main.py", line 115, in add_security_headers
    |     for key, value in SecurityHeaders.get_security_headers().items():
    |                       ^^^^^^^^^^^^^^^^^^^^^^^^^^^^^^^^^^^^
    | AttributeError: type object 'SecurityHeaders' has no attribute 'get_security_headers'
    +------------------------------------

During handling of the above exception, another exception occurred:

Traceback (most recent call last):
  File "c:\Users\ahmed\OneDrive\Desktop\Graduation_project\venv312\Lib\site-packages\starlette\middleware\errors.py", line 165, in __call__
    await self.app(scope, receive, _send)
  File "c:\Users\ahmed\OneDrive\Desktop\Graduation_project\venv312\Lib\site-packages\starlette\middleware\base.py", line 185, in __call__
    with collapse_excgroups():
  File "C:\Users\ahmed\AppData\Local\Programs\Python\Python312\Lib\contextlib.py", line 158, in __exit__
    self.gen.throw(value)
  File "c:\Users\ahmed\OneDrive\Desktop\Graduation_project\venv312\Lib\site-packages\starlette\_utils.py", line 82, in collapse_excgroups
    raise exc
  File "c:\Users\ahmed\OneDrive\Desktop\Graduation_project\venv312\Lib\site-packages\starlette\middleware\base.py", line 187, in __call__
    response = await self.dispatch_func(request, call_next)
               ^^^^^^^^^^^^^^^^^^^^^^^^^^^^^^^^^^^^^^^^^^^^
  File "C:\Users\ahmed\OneDrive\Desktop\Graduation_project\src\main.py", line 115, in add_security_headers
    for key, value in SecurityHeaders.get_security_headers().items():
                      ^^^^^^^^^^^^^^^^^^^^^^^^^^^^^^^^^^^^
AttributeError: type object 'SecurityHeaders' has no attribute 'get_security_headers'
2024-12-01 11:54:09,061 - src.main - ERROR - Unhandled error: type object 'SecurityHeaders' has no attribute 'get_security_headers' - [C:\Users\ahmed\OneDrive\Desktop\Graduation_project\src\main.py:95]
  + Exception Group Traceback (most recent call last):
  |   File "c:\Users\ahmed\OneDrive\Desktop\Graduation_project\venv312\Lib\site-packages\starlette\_utils.py", line 76, in collapse_excgroups
  |     yield
  |   File "c:\Users\ahmed\OneDrive\Desktop\Graduation_project\venv312\Lib\site-packages\starlette\middleware\base.py", line 186, in __call__
  |     async with anyio.create_task_group() as task_group:
  |   File "c:\Users\ahmed\OneDrive\Desktop\Graduation_project\venv312\Lib\site-packages\anyio\_backends\_asyncio.py", line 763, in __aexit__
  |     raise BaseExceptionGroup(
  | ExceptionGroup: unhandled errors in a TaskGroup (1 sub-exception)
  +-+---------------- 1 ----------------
    | Traceback (most recent call last):
    |   File "c:\Users\ahmed\OneDrive\Desktop\Graduation_project\venv312\Lib\site-packages\starlette\middleware\errors.py", line 165, in __call__
    |     await self.app(scope, receive, _send)
    |   File "c:\Users\ahmed\OneDrive\Desktop\Graduation_project\venv312\Lib\site-packages\starlette\middleware\base.py", line 185, in __call__
    |     with collapse_excgroups():
    |   File "C:\Users\ahmed\AppData\Local\Programs\Python\Python312\Lib\contextlib.py", line 158, in __exit__
    |     self.gen.throw(value)
    |   File "c:\Users\ahmed\OneDrive\Desktop\Graduation_project\venv312\Lib\site-packages\starlette\_utils.py", line 82, in collapse_excgroups
    |     raise exc
    |   File "c:\Users\ahmed\OneDrive\Desktop\Graduation_project\venv312\Lib\site-packages\starlette\middleware\base.py", line 187, in __call__
    |     response = await self.dispatch_func(request, call_next)
    |                ^^^^^^^^^^^^^^^^^^^^^^^^^^^^^^^^^^^^^^^^^^^^
    |   File "C:\Users\ahmed\OneDrive\Desktop\Graduation_project\src\main.py", line 115, in add_security_headers
    |     for key, value in SecurityHeaders.get_security_headers().items():
    |                       ^^^^^^^^^^^^^^^^^^^^^^^^^^^^^^^^^^^^
    | AttributeError: type object 'SecurityHeaders' has no attribute 'get_security_headers'
    +------------------------------------

During handling of the above exception, another exception occurred:

Traceback (most recent call last):
  File "c:\Users\ahmed\OneDrive\Desktop\Graduation_project\venv312\Lib\site-packages\starlette\middleware\errors.py", line 165, in __call__
    await self.app(scope, receive, _send)
  File "c:\Users\ahmed\OneDrive\Desktop\Graduation_project\venv312\Lib\site-packages\starlette\middleware\base.py", line 185, in __call__
    with collapse_excgroups():
  File "C:\Users\ahmed\AppData\Local\Programs\Python\Python312\Lib\contextlib.py", line 158, in __exit__
    self.gen.throw(value)
  File "c:\Users\ahmed\OneDrive\Desktop\Graduation_project\venv312\Lib\site-packages\starlette\_utils.py", line 82, in collapse_excgroups
    raise exc
  File "c:\Users\ahmed\OneDrive\Desktop\Graduation_project\venv312\Lib\site-packages\starlette\middleware\base.py", line 187, in __call__
    response = await self.dispatch_func(request, call_next)
               ^^^^^^^^^^^^^^^^^^^^^^^^^^^^^^^^^^^^^^^^^^^^
  File "C:\Users\ahmed\OneDrive\Desktop\Graduation_project\src\main.py", line 115, in add_security_headers
    for key, value in SecurityHeaders.get_security_headers().items():
                      ^^^^^^^^^^^^^^^^^^^^^^^^^^^^^^^^^^^^
AttributeError: type object 'SecurityHeaders' has no attribute 'get_security_headers'
2024-12-01 11:54:09,782 - src.main - ERROR - Unhandled error: type object 'SecurityHeaders' has no attribute 'get_security_headers' - [C:\Users\ahmed\OneDrive\Desktop\Graduation_project\src\main.py:95]
  + Exception Group Traceback (most recent call last):
  |   File "c:\Users\ahmed\OneDrive\Desktop\Graduation_project\venv312\Lib\site-packages\starlette\_utils.py", line 76, in collapse_excgroups
  |     yield
  |   File "c:\Users\ahmed\OneDrive\Desktop\Graduation_project\venv312\Lib\site-packages\starlette\middleware\base.py", line 186, in __call__
  |     async with anyio.create_task_group() as task_group:
  |   File "c:\Users\ahmed\OneDrive\Desktop\Graduation_project\venv312\Lib\site-packages\anyio\_backends\_asyncio.py", line 763, in __aexit__
  |     raise BaseExceptionGroup(
  | ExceptionGroup: unhandled errors in a TaskGroup (1 sub-exception)
  +-+---------------- 1 ----------------
    | Traceback (most recent call last):
    |   File "c:\Users\ahmed\OneDrive\Desktop\Graduation_project\venv312\Lib\site-packages\starlette\middleware\errors.py", line 165, in __call__
    |     await self.app(scope, receive, _send)
    |   File "c:\Users\ahmed\OneDrive\Desktop\Graduation_project\venv312\Lib\site-packages\starlette\middleware\base.py", line 185, in __call__
    |     with collapse_excgroups():
    |   File "C:\Users\ahmed\AppData\Local\Programs\Python\Python312\Lib\contextlib.py", line 158, in __exit__
    |     self.gen.throw(value)
    |   File "c:\Users\ahmed\OneDrive\Desktop\Graduation_project\venv312\Lib\site-packages\starlette\_utils.py", line 82, in collapse_excgroups
    |     raise exc
    |   File "c:\Users\ahmed\OneDrive\Desktop\Graduation_project\venv312\Lib\site-packages\starlette\middleware\base.py", line 187, in __call__
    |     response = await self.dispatch_func(request, call_next)
    |                ^^^^^^^^^^^^^^^^^^^^^^^^^^^^^^^^^^^^^^^^^^^^
    |   File "C:\Users\ahmed\OneDrive\Desktop\Graduation_project\src\main.py", line 115, in add_security_headers
    |     for key, value in SecurityHeaders.get_security_headers().items():
    |                       ^^^^^^^^^^^^^^^^^^^^^^^^^^^^^^^^^^^^
    | AttributeError: type object 'SecurityHeaders' has no attribute 'get_security_headers'
    +------------------------------------

During handling of the above exception, another exception occurred:

Traceback (most recent call last):
  File "c:\Users\ahmed\OneDrive\Desktop\Graduation_project\venv312\Lib\site-packages\starlette\middleware\errors.py", line 165, in __call__
    await self.app(scope, receive, _send)
  File "c:\Users\ahmed\OneDrive\Desktop\Graduation_project\venv312\Lib\site-packages\starlette\middleware\base.py", line 185, in __call__
    with collapse_excgroups():
  File "C:\Users\ahmed\AppData\Local\Programs\Python\Python312\Lib\contextlib.py", line 158, in __exit__
    self.gen.throw(value)
  File "c:\Users\ahmed\OneDrive\Desktop\Graduation_project\venv312\Lib\site-packages\starlette\_utils.py", line 82, in collapse_excgroups
    raise exc
  File "c:\Users\ahmed\OneDrive\Desktop\Graduation_project\venv312\Lib\site-packages\starlette\middleware\base.py", line 187, in __call__
    response = await self.dispatch_func(request, call_next)
               ^^^^^^^^^^^^^^^^^^^^^^^^^^^^^^^^^^^^^^^^^^^^
  File "C:\Users\ahmed\OneDrive\Desktop\Graduation_project\src\main.py", line 115, in add_security_headers
    for key, value in SecurityHeaders.get_security_headers().items():
                      ^^^^^^^^^^^^^^^^^^^^^^^^^^^^^^^^^^^^
AttributeError: type object 'SecurityHeaders' has no attribute 'get_security_headers'
2024-12-01 11:54:10,462 - src.main - ERROR - Unhandled error: type object 'SecurityHeaders' has no attribute 'get_security_headers' - [C:\Users\ahmed\OneDrive\Desktop\Graduation_project\src\main.py:95]
  + Exception Group Traceback (most recent call last):
  |   File "c:\Users\ahmed\OneDrive\Desktop\Graduation_project\venv312\Lib\site-packages\starlette\_utils.py", line 76, in collapse_excgroups
  |     yield
  |   File "c:\Users\ahmed\OneDrive\Desktop\Graduation_project\venv312\Lib\site-packages\starlette\middleware\base.py", line 186, in __call__
  |     async with anyio.create_task_group() as task_group:
  |   File "c:\Users\ahmed\OneDrive\Desktop\Graduation_project\venv312\Lib\site-packages\anyio\_backends\_asyncio.py", line 763, in __aexit__
  |     raise BaseExceptionGroup(
  | ExceptionGroup: unhandled errors in a TaskGroup (1 sub-exception)
  +-+---------------- 1 ----------------
    | Traceback (most recent call last):
    |   File "c:\Users\ahmed\OneDrive\Desktop\Graduation_project\venv312\Lib\site-packages\starlette\middleware\errors.py", line 165, in __call__
    |     await self.app(scope, receive, _send)
    |   File "c:\Users\ahmed\OneDrive\Desktop\Graduation_project\venv312\Lib\site-packages\starlette\middleware\base.py", line 185, in __call__
    |     with collapse_excgroups():
    |   File "C:\Users\ahmed\AppData\Local\Programs\Python\Python312\Lib\contextlib.py", line 158, in __exit__
    |     self.gen.throw(value)
    |   File "c:\Users\ahmed\OneDrive\Desktop\Graduation_project\venv312\Lib\site-packages\starlette\_utils.py", line 82, in collapse_excgroups
    |     raise exc
    |   File "c:\Users\ahmed\OneDrive\Desktop\Graduation_project\venv312\Lib\site-packages\starlette\middleware\base.py", line 187, in __call__
    |     response = await self.dispatch_func(request, call_next)
    |                ^^^^^^^^^^^^^^^^^^^^^^^^^^^^^^^^^^^^^^^^^^^^
    |   File "C:\Users\ahmed\OneDrive\Desktop\Graduation_project\src\main.py", line 115, in add_security_headers
    |     for key, value in SecurityHeaders.get_security_headers().items():
    |                       ^^^^^^^^^^^^^^^^^^^^^^^^^^^^^^^^^^^^
    | AttributeError: type object 'SecurityHeaders' has no attribute 'get_security_headers'
    +------------------------------------

During handling of the above exception, another exception occurred:

Traceback (most recent call last):
  File "c:\Users\ahmed\OneDrive\Desktop\Graduation_project\venv312\Lib\site-packages\starlette\middleware\errors.py", line 165, in __call__
    await self.app(scope, receive, _send)
  File "c:\Users\ahmed\OneDrive\Desktop\Graduation_project\venv312\Lib\site-packages\starlette\middleware\base.py", line 185, in __call__
    with collapse_excgroups():
  File "C:\Users\ahmed\AppData\Local\Programs\Python\Python312\Lib\contextlib.py", line 158, in __exit__
    self.gen.throw(value)
  File "c:\Users\ahmed\OneDrive\Desktop\Graduation_project\venv312\Lib\site-packages\starlette\_utils.py", line 82, in collapse_excgroups
    raise exc
  File "c:\Users\ahmed\OneDrive\Desktop\Graduation_project\venv312\Lib\site-packages\starlette\middleware\base.py", line 187, in __call__
    response = await self.dispatch_func(request, call_next)
               ^^^^^^^^^^^^^^^^^^^^^^^^^^^^^^^^^^^^^^^^^^^^
  File "C:\Users\ahmed\OneDrive\Desktop\Graduation_project\src\main.py", line 115, in add_security_headers
    for key, value in SecurityHeaders.get_security_headers().items():
                      ^^^^^^^^^^^^^^^^^^^^^^^^^^^^^^^^^^^^
AttributeError: type object 'SecurityHeaders' has no attribute 'get_security_headers'
2024-12-01 11:54:11,140 - src.main - ERROR - Unhandled error: type object 'SecurityHeaders' has no attribute 'get_security_headers' - [C:\Users\ahmed\OneDrive\Desktop\Graduation_project\src\main.py:95]
  + Exception Group Traceback (most recent call last):
  |   File "c:\Users\ahmed\OneDrive\Desktop\Graduation_project\venv312\Lib\site-packages\starlette\_utils.py", line 76, in collapse_excgroups
  |     yield
  |   File "c:\Users\ahmed\OneDrive\Desktop\Graduation_project\venv312\Lib\site-packages\starlette\middleware\base.py", line 186, in __call__
  |     async with anyio.create_task_group() as task_group:
  |   File "c:\Users\ahmed\OneDrive\Desktop\Graduation_project\venv312\Lib\site-packages\anyio\_backends\_asyncio.py", line 763, in __aexit__
  |     raise BaseExceptionGroup(
  | ExceptionGroup: unhandled errors in a TaskGroup (1 sub-exception)
  +-+---------------- 1 ----------------
    | Traceback (most recent call last):
    |   File "c:\Users\ahmed\OneDrive\Desktop\Graduation_project\venv312\Lib\site-packages\starlette\middleware\errors.py", line 165, in __call__
    |     await self.app(scope, receive, _send)
    |   File "c:\Users\ahmed\OneDrive\Desktop\Graduation_project\venv312\Lib\site-packages\starlette\middleware\base.py", line 185, in __call__
    |     with collapse_excgroups():
    |   File "C:\Users\ahmed\AppData\Local\Programs\Python\Python312\Lib\contextlib.py", line 158, in __exit__
    |     self.gen.throw(value)
    |   File "c:\Users\ahmed\OneDrive\Desktop\Graduation_project\venv312\Lib\site-packages\starlette\_utils.py", line 82, in collapse_excgroups
    |     raise exc
    |   File "c:\Users\ahmed\OneDrive\Desktop\Graduation_project\venv312\Lib\site-packages\starlette\middleware\base.py", line 187, in __call__
    |     response = await self.dispatch_func(request, call_next)
    |                ^^^^^^^^^^^^^^^^^^^^^^^^^^^^^^^^^^^^^^^^^^^^
    |   File "C:\Users\ahmed\OneDrive\Desktop\Graduation_project\src\main.py", line 115, in add_security_headers
    |     for key, value in SecurityHeaders.get_security_headers().items():
    |                       ^^^^^^^^^^^^^^^^^^^^^^^^^^^^^^^^^^^^
    | AttributeError: type object 'SecurityHeaders' has no attribute 'get_security_headers'
    +------------------------------------

During handling of the above exception, another exception occurred:

Traceback (most recent call last):
  File "c:\Users\ahmed\OneDrive\Desktop\Graduation_project\venv312\Lib\site-packages\starlette\middleware\errors.py", line 165, in __call__
    await self.app(scope, receive, _send)
  File "c:\Users\ahmed\OneDrive\Desktop\Graduation_project\venv312\Lib\site-packages\starlette\middleware\base.py", line 185, in __call__
    with collapse_excgroups():
  File "C:\Users\ahmed\AppData\Local\Programs\Python\Python312\Lib\contextlib.py", line 158, in __exit__
    self.gen.throw(value)
  File "c:\Users\ahmed\OneDrive\Desktop\Graduation_project\venv312\Lib\site-packages\starlette\_utils.py", line 82, in collapse_excgroups
    raise exc
  File "c:\Users\ahmed\OneDrive\Desktop\Graduation_project\venv312\Lib\site-packages\starlette\middleware\base.py", line 187, in __call__
    response = await self.dispatch_func(request, call_next)
               ^^^^^^^^^^^^^^^^^^^^^^^^^^^^^^^^^^^^^^^^^^^^
  File "C:\Users\ahmed\OneDrive\Desktop\Graduation_project\src\main.py", line 115, in add_security_headers
    for key, value in SecurityHeaders.get_security_headers().items():
                      ^^^^^^^^^^^^^^^^^^^^^^^^^^^^^^^^^^^^
AttributeError: type object 'SecurityHeaders' has no attribute 'get_security_headers'
2024-12-01 11:54:11,820 - src.main - ERROR - Unhandled error: type object 'SecurityHeaders' has no attribute 'get_security_headers' - [C:\Users\ahmed\OneDrive\Desktop\Graduation_project\src\main.py:95]
  + Exception Group Traceback (most recent call last):
  |   File "c:\Users\ahmed\OneDrive\Desktop\Graduation_project\venv312\Lib\site-packages\starlette\_utils.py", line 76, in collapse_excgroups
  |     yield
  |   File "c:\Users\ahmed\OneDrive\Desktop\Graduation_project\venv312\Lib\site-packages\starlette\middleware\base.py", line 186, in __call__
  |     async with anyio.create_task_group() as task_group:
  |   File "c:\Users\ahmed\OneDrive\Desktop\Graduation_project\venv312\Lib\site-packages\anyio\_backends\_asyncio.py", line 763, in __aexit__
  |     raise BaseExceptionGroup(
  | ExceptionGroup: unhandled errors in a TaskGroup (1 sub-exception)
  +-+---------------- 1 ----------------
    | Traceback (most recent call last):
    |   File "c:\Users\ahmed\OneDrive\Desktop\Graduation_project\venv312\Lib\site-packages\starlette\middleware\errors.py", line 165, in __call__
    |     await self.app(scope, receive, _send)
    |   File "c:\Users\ahmed\OneDrive\Desktop\Graduation_project\venv312\Lib\site-packages\starlette\middleware\base.py", line 185, in __call__
    |     with collapse_excgroups():
    |   File "C:\Users\ahmed\AppData\Local\Programs\Python\Python312\Lib\contextlib.py", line 158, in __exit__
    |     self.gen.throw(value)
    |   File "c:\Users\ahmed\OneDrive\Desktop\Graduation_project\venv312\Lib\site-packages\starlette\_utils.py", line 82, in collapse_excgroups
    |     raise exc
    |   File "c:\Users\ahmed\OneDrive\Desktop\Graduation_project\venv312\Lib\site-packages\starlette\middleware\base.py", line 187, in __call__
    |     response = await self.dispatch_func(request, call_next)
    |                ^^^^^^^^^^^^^^^^^^^^^^^^^^^^^^^^^^^^^^^^^^^^
    |   File "C:\Users\ahmed\OneDrive\Desktop\Graduation_project\src\main.py", line 115, in add_security_headers
    |     for key, value in SecurityHeaders.get_security_headers().items():
    |                       ^^^^^^^^^^^^^^^^^^^^^^^^^^^^^^^^^^^^
    | AttributeError: type object 'SecurityHeaders' has no attribute 'get_security_headers'
    +------------------------------------

During handling of the above exception, another exception occurred:

Traceback (most recent call last):
  File "c:\Users\ahmed\OneDrive\Desktop\Graduation_project\venv312\Lib\site-packages\starlette\middleware\errors.py", line 165, in __call__
    await self.app(scope, receive, _send)
  File "c:\Users\ahmed\OneDrive\Desktop\Graduation_project\venv312\Lib\site-packages\starlette\middleware\base.py", line 185, in __call__
    with collapse_excgroups():
  File "C:\Users\ahmed\AppData\Local\Programs\Python\Python312\Lib\contextlib.py", line 158, in __exit__
    self.gen.throw(value)
  File "c:\Users\ahmed\OneDrive\Desktop\Graduation_project\venv312\Lib\site-packages\starlette\_utils.py", line 82, in collapse_excgroups
    raise exc
  File "c:\Users\ahmed\OneDrive\Desktop\Graduation_project\venv312\Lib\site-packages\starlette\middleware\base.py", line 187, in __call__
    response = await self.dispatch_func(request, call_next)
               ^^^^^^^^^^^^^^^^^^^^^^^^^^^^^^^^^^^^^^^^^^^^
  File "C:\Users\ahmed\OneDrive\Desktop\Graduation_project\src\main.py", line 115, in add_security_headers
    for key, value in SecurityHeaders.get_security_headers().items():
                      ^^^^^^^^^^^^^^^^^^^^^^^^^^^^^^^^^^^^
AttributeError: type object 'SecurityHeaders' has no attribute 'get_security_headers'
2024-12-01 11:54:12,512 - src.main - ERROR - Unhandled error: type object 'SecurityHeaders' has no attribute 'get_security_headers' - [C:\Users\ahmed\OneDrive\Desktop\Graduation_project\src\main.py:95]
  + Exception Group Traceback (most recent call last):
  |   File "c:\Users\ahmed\OneDrive\Desktop\Graduation_project\venv312\Lib\site-packages\starlette\_utils.py", line 76, in collapse_excgroups
  |     yield
  |   File "c:\Users\ahmed\OneDrive\Desktop\Graduation_project\venv312\Lib\site-packages\starlette\middleware\base.py", line 186, in __call__
  |     async with anyio.create_task_group() as task_group:
  |   File "c:\Users\ahmed\OneDrive\Desktop\Graduation_project\venv312\Lib\site-packages\anyio\_backends\_asyncio.py", line 763, in __aexit__
  |     raise BaseExceptionGroup(
  | ExceptionGroup: unhandled errors in a TaskGroup (1 sub-exception)
  +-+---------------- 1 ----------------
    | Traceback (most recent call last):
    |   File "c:\Users\ahmed\OneDrive\Desktop\Graduation_project\venv312\Lib\site-packages\starlette\middleware\errors.py", line 165, in __call__
    |     await self.app(scope, receive, _send)
    |   File "c:\Users\ahmed\OneDrive\Desktop\Graduation_project\venv312\Lib\site-packages\starlette\middleware\base.py", line 185, in __call__
    |     with collapse_excgroups():
    |   File "C:\Users\ahmed\AppData\Local\Programs\Python\Python312\Lib\contextlib.py", line 158, in __exit__
    |     self.gen.throw(value)
    |   File "c:\Users\ahmed\OneDrive\Desktop\Graduation_project\venv312\Lib\site-packages\starlette\_utils.py", line 82, in collapse_excgroups
    |     raise exc
    |   File "c:\Users\ahmed\OneDrive\Desktop\Graduation_project\venv312\Lib\site-packages\starlette\middleware\base.py", line 187, in __call__
    |     response = await self.dispatch_func(request, call_next)
    |                ^^^^^^^^^^^^^^^^^^^^^^^^^^^^^^^^^^^^^^^^^^^^
    |   File "C:\Users\ahmed\OneDrive\Desktop\Graduation_project\src\main.py", line 115, in add_security_headers
    |     for key, value in SecurityHeaders.get_security_headers().items():
    |                       ^^^^^^^^^^^^^^^^^^^^^^^^^^^^^^^^^^^^
    | AttributeError: type object 'SecurityHeaders' has no attribute 'get_security_headers'
    +------------------------------------

During handling of the above exception, another exception occurred:

Traceback (most recent call last):
  File "c:\Users\ahmed\OneDrive\Desktop\Graduation_project\venv312\Lib\site-packages\starlette\middleware\errors.py", line 165, in __call__
    await self.app(scope, receive, _send)
  File "c:\Users\ahmed\OneDrive\Desktop\Graduation_project\venv312\Lib\site-packages\starlette\middleware\base.py", line 185, in __call__
    with collapse_excgroups():
  File "C:\Users\ahmed\AppData\Local\Programs\Python\Python312\Lib\contextlib.py", line 158, in __exit__
    self.gen.throw(value)
  File "c:\Users\ahmed\OneDrive\Desktop\Graduation_project\venv312\Lib\site-packages\starlette\_utils.py", line 82, in collapse_excgroups
    raise exc
  File "c:\Users\ahmed\OneDrive\Desktop\Graduation_project\venv312\Lib\site-packages\starlette\middleware\base.py", line 187, in __call__
    response = await self.dispatch_func(request, call_next)
               ^^^^^^^^^^^^^^^^^^^^^^^^^^^^^^^^^^^^^^^^^^^^
  File "C:\Users\ahmed\OneDrive\Desktop\Graduation_project\src\main.py", line 115, in add_security_headers
    for key, value in SecurityHeaders.get_security_headers().items():
                      ^^^^^^^^^^^^^^^^^^^^^^^^^^^^^^^^^^^^
AttributeError: type object 'SecurityHeaders' has no attribute 'get_security_headers'
2024-12-01 11:54:13,162 - src.main - ERROR - Unhandled error: type object 'SecurityHeaders' has no attribute 'get_security_headers' - [C:\Users\ahmed\OneDrive\Desktop\Graduation_project\src\main.py:95]
  + Exception Group Traceback (most recent call last):
  |   File "c:\Users\ahmed\OneDrive\Desktop\Graduation_project\venv312\Lib\site-packages\starlette\_utils.py", line 76, in collapse_excgroups
  |     yield
  |   File "c:\Users\ahmed\OneDrive\Desktop\Graduation_project\venv312\Lib\site-packages\starlette\middleware\base.py", line 186, in __call__
  |     async with anyio.create_task_group() as task_group:
  |   File "c:\Users\ahmed\OneDrive\Desktop\Graduation_project\venv312\Lib\site-packages\anyio\_backends\_asyncio.py", line 763, in __aexit__
  |     raise BaseExceptionGroup(
  | ExceptionGroup: unhandled errors in a TaskGroup (1 sub-exception)
  +-+---------------- 1 ----------------
    | Traceback (most recent call last):
    |   File "c:\Users\ahmed\OneDrive\Desktop\Graduation_project\venv312\Lib\site-packages\starlette\middleware\errors.py", line 165, in __call__
    |     await self.app(scope, receive, _send)
    |   File "c:\Users\ahmed\OneDrive\Desktop\Graduation_project\venv312\Lib\site-packages\starlette\middleware\base.py", line 185, in __call__
    |     with collapse_excgroups():
    |   File "C:\Users\ahmed\AppData\Local\Programs\Python\Python312\Lib\contextlib.py", line 158, in __exit__
    |     self.gen.throw(value)
    |   File "c:\Users\ahmed\OneDrive\Desktop\Graduation_project\venv312\Lib\site-packages\starlette\_utils.py", line 82, in collapse_excgroups
    |     raise exc
    |   File "c:\Users\ahmed\OneDrive\Desktop\Graduation_project\venv312\Lib\site-packages\starlette\middleware\base.py", line 187, in __call__
    |     response = await self.dispatch_func(request, call_next)
    |                ^^^^^^^^^^^^^^^^^^^^^^^^^^^^^^^^^^^^^^^^^^^^
    |   File "C:\Users\ahmed\OneDrive\Desktop\Graduation_project\src\main.py", line 115, in add_security_headers
    |     for key, value in SecurityHeaders.get_security_headers().items():
    |                       ^^^^^^^^^^^^^^^^^^^^^^^^^^^^^^^^^^^^
    | AttributeError: type object 'SecurityHeaders' has no attribute 'get_security_headers'
    +------------------------------------

During handling of the above exception, another exception occurred:

Traceback (most recent call last):
  File "c:\Users\ahmed\OneDrive\Desktop\Graduation_project\venv312\Lib\site-packages\starlette\middleware\errors.py", line 165, in __call__
    await self.app(scope, receive, _send)
  File "c:\Users\ahmed\OneDrive\Desktop\Graduation_project\venv312\Lib\site-packages\starlette\middleware\base.py", line 185, in __call__
    with collapse_excgroups():
  File "C:\Users\ahmed\AppData\Local\Programs\Python\Python312\Lib\contextlib.py", line 158, in __exit__
    self.gen.throw(value)
  File "c:\Users\ahmed\OneDrive\Desktop\Graduation_project\venv312\Lib\site-packages\starlette\_utils.py", line 82, in collapse_excgroups
    raise exc
  File "c:\Users\ahmed\OneDrive\Desktop\Graduation_project\venv312\Lib\site-packages\starlette\middleware\base.py", line 187, in __call__
    response = await self.dispatch_func(request, call_next)
               ^^^^^^^^^^^^^^^^^^^^^^^^^^^^^^^^^^^^^^^^^^^^
  File "C:\Users\ahmed\OneDrive\Desktop\Graduation_project\src\main.py", line 115, in add_security_headers
    for key, value in SecurityHeaders.get_security_headers().items():
                      ^^^^^^^^^^^^^^^^^^^^^^^^^^^^^^^^^^^^
AttributeError: type object 'SecurityHeaders' has no attribute 'get_security_headers'
2024-12-01 11:54:13,839 - src.main - ERROR - Unhandled error: type object 'SecurityHeaders' has no attribute 'get_security_headers' - [C:\Users\ahmed\OneDrive\Desktop\Graduation_project\src\main.py:95]
  + Exception Group Traceback (most recent call last):
  |   File "c:\Users\ahmed\OneDrive\Desktop\Graduation_project\venv312\Lib\site-packages\starlette\_utils.py", line 76, in collapse_excgroups
  |     yield
  |   File "c:\Users\ahmed\OneDrive\Desktop\Graduation_project\venv312\Lib\site-packages\starlette\middleware\base.py", line 186, in __call__
  |     async with anyio.create_task_group() as task_group:
  |   File "c:\Users\ahmed\OneDrive\Desktop\Graduation_project\venv312\Lib\site-packages\anyio\_backends\_asyncio.py", line 763, in __aexit__
  |     raise BaseExceptionGroup(
  | ExceptionGroup: unhandled errors in a TaskGroup (1 sub-exception)
  +-+---------------- 1 ----------------
    | Traceback (most recent call last):
    |   File "c:\Users\ahmed\OneDrive\Desktop\Graduation_project\venv312\Lib\site-packages\starlette\middleware\errors.py", line 165, in __call__
    |     await self.app(scope, receive, _send)
    |   File "c:\Users\ahmed\OneDrive\Desktop\Graduation_project\venv312\Lib\site-packages\starlette\middleware\base.py", line 185, in __call__
    |     with collapse_excgroups():
    |   File "C:\Users\ahmed\AppData\Local\Programs\Python\Python312\Lib\contextlib.py", line 158, in __exit__
    |     self.gen.throw(value)
    |   File "c:\Users\ahmed\OneDrive\Desktop\Graduation_project\venv312\Lib\site-packages\starlette\_utils.py", line 82, in collapse_excgroups
    |     raise exc
    |   File "c:\Users\ahmed\OneDrive\Desktop\Graduation_project\venv312\Lib\site-packages\starlette\middleware\base.py", line 187, in __call__
    |     response = await self.dispatch_func(request, call_next)
    |                ^^^^^^^^^^^^^^^^^^^^^^^^^^^^^^^^^^^^^^^^^^^^
    |   File "C:\Users\ahmed\OneDrive\Desktop\Graduation_project\src\main.py", line 115, in add_security_headers
    |     for key, value in SecurityHeaders.get_security_headers().items():
    |                       ^^^^^^^^^^^^^^^^^^^^^^^^^^^^^^^^^^^^
    | AttributeError: type object 'SecurityHeaders' has no attribute 'get_security_headers'
    +------------------------------------

During handling of the above exception, another exception occurred:

Traceback (most recent call last):
  File "c:\Users\ahmed\OneDrive\Desktop\Graduation_project\venv312\Lib\site-packages\starlette\middleware\errors.py", line 165, in __call__
    await self.app(scope, receive, _send)
  File "c:\Users\ahmed\OneDrive\Desktop\Graduation_project\venv312\Lib\site-packages\starlette\middleware\base.py", line 185, in __call__
    with collapse_excgroups():
  File "C:\Users\ahmed\AppData\Local\Programs\Python\Python312\Lib\contextlib.py", line 158, in __exit__
    self.gen.throw(value)
  File "c:\Users\ahmed\OneDrive\Desktop\Graduation_project\venv312\Lib\site-packages\starlette\_utils.py", line 82, in collapse_excgroups
    raise exc
  File "c:\Users\ahmed\OneDrive\Desktop\Graduation_project\venv312\Lib\site-packages\starlette\middleware\base.py", line 187, in __call__
    response = await self.dispatch_func(request, call_next)
               ^^^^^^^^^^^^^^^^^^^^^^^^^^^^^^^^^^^^^^^^^^^^
  File "C:\Users\ahmed\OneDrive\Desktop\Graduation_project\src\main.py", line 115, in add_security_headers
    for key, value in SecurityHeaders.get_security_headers().items():
                      ^^^^^^^^^^^^^^^^^^^^^^^^^^^^^^^^^^^^
AttributeError: type object 'SecurityHeaders' has no attribute 'get_security_headers'
2024-12-01 11:54:14,501 - src.main - ERROR - Unhandled error: type object 'SecurityHeaders' has no attribute 'get_security_headers' - [C:\Users\ahmed\OneDrive\Desktop\Graduation_project\src\main.py:95]
  + Exception Group Traceback (most recent call last):
  |   File "c:\Users\ahmed\OneDrive\Desktop\Graduation_project\venv312\Lib\site-packages\starlette\_utils.py", line 76, in collapse_excgroups
  |     yield
  |   File "c:\Users\ahmed\OneDrive\Desktop\Graduation_project\venv312\Lib\site-packages\starlette\middleware\base.py", line 186, in __call__
  |     async with anyio.create_task_group() as task_group:
  |   File "c:\Users\ahmed\OneDrive\Desktop\Graduation_project\venv312\Lib\site-packages\anyio\_backends\_asyncio.py", line 763, in __aexit__
  |     raise BaseExceptionGroup(
  | ExceptionGroup: unhandled errors in a TaskGroup (1 sub-exception)
  +-+---------------- 1 ----------------
    | Traceback (most recent call last):
    |   File "c:\Users\ahmed\OneDrive\Desktop\Graduation_project\venv312\Lib\site-packages\starlette\middleware\errors.py", line 165, in __call__
    |     await self.app(scope, receive, _send)
    |   File "c:\Users\ahmed\OneDrive\Desktop\Graduation_project\venv312\Lib\site-packages\starlette\middleware\base.py", line 185, in __call__
    |     with collapse_excgroups():
    |   File "C:\Users\ahmed\AppData\Local\Programs\Python\Python312\Lib\contextlib.py", line 158, in __exit__
    |     self.gen.throw(value)
    |   File "c:\Users\ahmed\OneDrive\Desktop\Graduation_project\venv312\Lib\site-packages\starlette\_utils.py", line 82, in collapse_excgroups
    |     raise exc
    |   File "c:\Users\ahmed\OneDrive\Desktop\Graduation_project\venv312\Lib\site-packages\starlette\middleware\base.py", line 187, in __call__
    |     response = await self.dispatch_func(request, call_next)
    |                ^^^^^^^^^^^^^^^^^^^^^^^^^^^^^^^^^^^^^^^^^^^^
    |   File "C:\Users\ahmed\OneDrive\Desktop\Graduation_project\src\main.py", line 115, in add_security_headers
    |     for key, value in SecurityHeaders.get_security_headers().items():
    |                       ^^^^^^^^^^^^^^^^^^^^^^^^^^^^^^^^^^^^
    | AttributeError: type object 'SecurityHeaders' has no attribute 'get_security_headers'
    +------------------------------------

During handling of the above exception, another exception occurred:

Traceback (most recent call last):
  File "c:\Users\ahmed\OneDrive\Desktop\Graduation_project\venv312\Lib\site-packages\starlette\middleware\errors.py", line 165, in __call__
    await self.app(scope, receive, _send)
  File "c:\Users\ahmed\OneDrive\Desktop\Graduation_project\venv312\Lib\site-packages\starlette\middleware\base.py", line 185, in __call__
    with collapse_excgroups():
  File "C:\Users\ahmed\AppData\Local\Programs\Python\Python312\Lib\contextlib.py", line 158, in __exit__
    self.gen.throw(value)
  File "c:\Users\ahmed\OneDrive\Desktop\Graduation_project\venv312\Lib\site-packages\starlette\_utils.py", line 82, in collapse_excgroups
    raise exc
  File "c:\Users\ahmed\OneDrive\Desktop\Graduation_project\venv312\Lib\site-packages\starlette\middleware\base.py", line 187, in __call__
    response = await self.dispatch_func(request, call_next)
               ^^^^^^^^^^^^^^^^^^^^^^^^^^^^^^^^^^^^^^^^^^^^
  File "C:\Users\ahmed\OneDrive\Desktop\Graduation_project\src\main.py", line 115, in add_security_headers
    for key, value in SecurityHeaders.get_security_headers().items():
                      ^^^^^^^^^^^^^^^^^^^^^^^^^^^^^^^^^^^^
AttributeError: type object 'SecurityHeaders' has no attribute 'get_security_headers'
2024-12-01 11:54:15,215 - src.main - ERROR - Unhandled error: type object 'SecurityHeaders' has no attribute 'get_security_headers' - [C:\Users\ahmed\OneDrive\Desktop\Graduation_project\src\main.py:95]
  + Exception Group Traceback (most recent call last):
  |   File "c:\Users\ahmed\OneDrive\Desktop\Graduation_project\venv312\Lib\site-packages\starlette\_utils.py", line 76, in collapse_excgroups
  |     yield
  |   File "c:\Users\ahmed\OneDrive\Desktop\Graduation_project\venv312\Lib\site-packages\starlette\middleware\base.py", line 186, in __call__
  |     async with anyio.create_task_group() as task_group:
  |   File "c:\Users\ahmed\OneDrive\Desktop\Graduation_project\venv312\Lib\site-packages\anyio\_backends\_asyncio.py", line 763, in __aexit__
  |     raise BaseExceptionGroup(
  | ExceptionGroup: unhandled errors in a TaskGroup (1 sub-exception)
  +-+---------------- 1 ----------------
    | Traceback (most recent call last):
    |   File "c:\Users\ahmed\OneDrive\Desktop\Graduation_project\venv312\Lib\site-packages\starlette\middleware\errors.py", line 165, in __call__
    |     await self.app(scope, receive, _send)
    |   File "c:\Users\ahmed\OneDrive\Desktop\Graduation_project\venv312\Lib\site-packages\starlette\middleware\base.py", line 185, in __call__
    |     with collapse_excgroups():
    |   File "C:\Users\ahmed\AppData\Local\Programs\Python\Python312\Lib\contextlib.py", line 158, in __exit__
    |     self.gen.throw(value)
    |   File "c:\Users\ahmed\OneDrive\Desktop\Graduation_project\venv312\Lib\site-packages\starlette\_utils.py", line 82, in collapse_excgroups
    |     raise exc
    |   File "c:\Users\ahmed\OneDrive\Desktop\Graduation_project\venv312\Lib\site-packages\starlette\middleware\base.py", line 187, in __call__
    |     response = await self.dispatch_func(request, call_next)
    |                ^^^^^^^^^^^^^^^^^^^^^^^^^^^^^^^^^^^^^^^^^^^^
    |   File "C:\Users\ahmed\OneDrive\Desktop\Graduation_project\src\main.py", line 115, in add_security_headers
    |     for key, value in SecurityHeaders.get_security_headers().items():
    |                       ^^^^^^^^^^^^^^^^^^^^^^^^^^^^^^^^^^^^
    | AttributeError: type object 'SecurityHeaders' has no attribute 'get_security_headers'
    +------------------------------------

During handling of the above exception, another exception occurred:

Traceback (most recent call last):
  File "c:\Users\ahmed\OneDrive\Desktop\Graduation_project\venv312\Lib\site-packages\starlette\middleware\errors.py", line 165, in __call__
    await self.app(scope, receive, _send)
  File "c:\Users\ahmed\OneDrive\Desktop\Graduation_project\venv312\Lib\site-packages\starlette\middleware\base.py", line 185, in __call__
    with collapse_excgroups():
  File "C:\Users\ahmed\AppData\Local\Programs\Python\Python312\Lib\contextlib.py", line 158, in __exit__
    self.gen.throw(value)
  File "c:\Users\ahmed\OneDrive\Desktop\Graduation_project\venv312\Lib\site-packages\starlette\_utils.py", line 82, in collapse_excgroups
    raise exc
  File "c:\Users\ahmed\OneDrive\Desktop\Graduation_project\venv312\Lib\site-packages\starlette\middleware\base.py", line 187, in __call__
    response = await self.dispatch_func(request, call_next)
               ^^^^^^^^^^^^^^^^^^^^^^^^^^^^^^^^^^^^^^^^^^^^
  File "C:\Users\ahmed\OneDrive\Desktop\Graduation_project\src\main.py", line 115, in add_security_headers
    for key, value in SecurityHeaders.get_security_headers().items():
                      ^^^^^^^^^^^^^^^^^^^^^^^^^^^^^^^^^^^^
AttributeError: type object 'SecurityHeaders' has no attribute 'get_security_headers'
2024-12-01 11:54:15,824 - src.main - ERROR - Unhandled error: type object 'SecurityHeaders' has no attribute 'get_security_headers' - [C:\Users\ahmed\OneDrive\Desktop\Graduation_project\src\main.py:95]
  + Exception Group Traceback (most recent call last):
  |   File "c:\Users\ahmed\OneDrive\Desktop\Graduation_project\venv312\Lib\site-packages\starlette\_utils.py", line 76, in collapse_excgroups
  |     yield
  |   File "c:\Users\ahmed\OneDrive\Desktop\Graduation_project\venv312\Lib\site-packages\starlette\middleware\base.py", line 186, in __call__
  |     async with anyio.create_task_group() as task_group:
  |   File "c:\Users\ahmed\OneDrive\Desktop\Graduation_project\venv312\Lib\site-packages\anyio\_backends\_asyncio.py", line 763, in __aexit__
  |     raise BaseExceptionGroup(
  | ExceptionGroup: unhandled errors in a TaskGroup (1 sub-exception)
  +-+---------------- 1 ----------------
    | Traceback (most recent call last):
    |   File "c:\Users\ahmed\OneDrive\Desktop\Graduation_project\venv312\Lib\site-packages\starlette\middleware\errors.py", line 165, in __call__
    |     await self.app(scope, receive, _send)
    |   File "c:\Users\ahmed\OneDrive\Desktop\Graduation_project\venv312\Lib\site-packages\starlette\middleware\base.py", line 185, in __call__
    |     with collapse_excgroups():
    |   File "C:\Users\ahmed\AppData\Local\Programs\Python\Python312\Lib\contextlib.py", line 158, in __exit__
    |     self.gen.throw(value)
    |   File "c:\Users\ahmed\OneDrive\Desktop\Graduation_project\venv312\Lib\site-packages\starlette\_utils.py", line 82, in collapse_excgroups
    |     raise exc
    |   File "c:\Users\ahmed\OneDrive\Desktop\Graduation_project\venv312\Lib\site-packages\starlette\middleware\base.py", line 187, in __call__
    |     response = await self.dispatch_func(request, call_next)
    |                ^^^^^^^^^^^^^^^^^^^^^^^^^^^^^^^^^^^^^^^^^^^^
    |   File "C:\Users\ahmed\OneDrive\Desktop\Graduation_project\src\main.py", line 115, in add_security_headers
    |     for key, value in SecurityHeaders.get_security_headers().items():
    |                       ^^^^^^^^^^^^^^^^^^^^^^^^^^^^^^^^^^^^
    | AttributeError: type object 'SecurityHeaders' has no attribute 'get_security_headers'
    +------------------------------------

During handling of the above exception, another exception occurred:

Traceback (most recent call last):
  File "c:\Users\ahmed\OneDrive\Desktop\Graduation_project\venv312\Lib\site-packages\starlette\middleware\errors.py", line 165, in __call__
    await self.app(scope, receive, _send)
  File "c:\Users\ahmed\OneDrive\Desktop\Graduation_project\venv312\Lib\site-packages\starlette\middleware\base.py", line 185, in __call__
    with collapse_excgroups():
  File "C:\Users\ahmed\AppData\Local\Programs\Python\Python312\Lib\contextlib.py", line 158, in __exit__
    self.gen.throw(value)
  File "c:\Users\ahmed\OneDrive\Desktop\Graduation_project\venv312\Lib\site-packages\starlette\_utils.py", line 82, in collapse_excgroups
    raise exc
  File "c:\Users\ahmed\OneDrive\Desktop\Graduation_project\venv312\Lib\site-packages\starlette\middleware\base.py", line 187, in __call__
    response = await self.dispatch_func(request, call_next)
               ^^^^^^^^^^^^^^^^^^^^^^^^^^^^^^^^^^^^^^^^^^^^
  File "C:\Users\ahmed\OneDrive\Desktop\Graduation_project\src\main.py", line 115, in add_security_headers
    for key, value in SecurityHeaders.get_security_headers().items():
                      ^^^^^^^^^^^^^^^^^^^^^^^^^^^^^^^^^^^^
AttributeError: type object 'SecurityHeaders' has no attribute 'get_security_headers'
2024-12-01 12:06:44,864 - src.main - ERROR - Validation error: [{'type': 'missing', 'loc': ('body', 'username'), 'msg': 'Field required', 'input': {'email': 'test@example.com', 'password': 'Test@123', 'first_name': 'Test', 'last_name': 'User'}}, {'type': 'missing', 'loc': ('body', 'full_name'), 'msg': 'Field required', 'input': {'email': 'test@example.com', 'password': 'Test@123', 'first_name': 'Test', 'last_name': 'User'}}] - [C:\Users\ahmed\OneDrive\Desktop\Graduation_project\src\main.py:74]
2024-12-01 12:06:44,975 - src.main - ERROR - Unhandled error: 'AuthService' object has no attribute 'login' - [C:\Users\ahmed\OneDrive\Desktop\Graduation_project\src\main.py:95]
  + Exception Group Traceback (most recent call last):
  |   File "c:\Users\ahmed\OneDrive\Desktop\Graduation_project\venv312\Lib\site-packages\starlette\_utils.py", line 76, in collapse_excgroups
  |     yield
  |   File "c:\Users\ahmed\OneDrive\Desktop\Graduation_project\venv312\Lib\site-packages\starlette\middleware\base.py", line 186, in __call__
  |     async with anyio.create_task_group() as task_group:
  |   File "c:\Users\ahmed\OneDrive\Desktop\Graduation_project\venv312\Lib\site-packages\anyio\_backends\_asyncio.py", line 763, in __aexit__
  |     raise BaseExceptionGroup(
  | ExceptionGroup: unhandled errors in a TaskGroup (1 sub-exception)
  +-+---------------- 1 ----------------
    | Traceback (most recent call last):
    |   File "c:\Users\ahmed\OneDrive\Desktop\Graduation_project\venv312\Lib\site-packages\starlette\middleware\errors.py", line 165, in __call__
    |     await self.app(scope, receive, _send)
    |   File "c:\Users\ahmed\OneDrive\Desktop\Graduation_project\venv312\Lib\site-packages\starlette\middleware\base.py", line 185, in __call__
    |     with collapse_excgroups():
    |   File "C:\Users\ahmed\AppData\Local\Programs\Python\Python312\Lib\contextlib.py", line 158, in __exit__
    |     self.gen.throw(value)
    |   File "c:\Users\ahmed\OneDrive\Desktop\Graduation_project\venv312\Lib\site-packages\starlette\_utils.py", line 82, in collapse_excgroups
    |     raise exc
    |   File "c:\Users\ahmed\OneDrive\Desktop\Graduation_project\venv312\Lib\site-packages\starlette\middleware\base.py", line 187, in __call__
    |     response = await self.dispatch_func(request, call_next)
    |                ^^^^^^^^^^^^^^^^^^^^^^^^^^^^^^^^^^^^^^^^^^^^
    |   File "C:\Users\ahmed\OneDrive\Desktop\Graduation_project\src\main.py", line 114, in add_security_headers
    |     response = await call_next(request)
    |                ^^^^^^^^^^^^^^^^^^^^^^^^
    |   File "c:\Users\ahmed\OneDrive\Desktop\Graduation_project\venv312\Lib\site-packages\starlette\middleware\base.py", line 163, in call_next
    |     raise app_exc
    |   File "c:\Users\ahmed\OneDrive\Desktop\Graduation_project\venv312\Lib\site-packages\starlette\middleware\base.py", line 149, in coro
    |     await self.app(scope, receive_or_disconnect, send_no_error)
    |   File "c:\Users\ahmed\OneDrive\Desktop\Graduation_project\venv312\Lib\site-packages\starlette\middleware\base.py", line 185, in __call__
    |     with collapse_excgroups():
    |   File "C:\Users\ahmed\AppData\Local\Programs\Python\Python312\Lib\contextlib.py", line 158, in __exit__
    |     self.gen.throw(value)
    |   File "c:\Users\ahmed\OneDrive\Desktop\Graduation_project\venv312\Lib\site-packages\starlette\_utils.py", line 82, in collapse_excgroups
    |     raise exc
    |   File "c:\Users\ahmed\OneDrive\Desktop\Graduation_project\venv312\Lib\site-packages\starlette\middleware\base.py", line 187, in __call__
    |     response = await self.dispatch_func(request, call_next)
    |                ^^^^^^^^^^^^^^^^^^^^^^^^^^^^^^^^^^^^^^^^^^^^
    |   File "C:\Users\ahmed\OneDrive\Desktop\Graduation_project\src\middleware\auth_middleware.py", line 78, in __call__
    |     return await call_next(request)
    |            ^^^^^^^^^^^^^^^^^^^^^^^^
    |   File "c:\Users\ahmed\OneDrive\Desktop\Graduation_project\venv312\Lib\site-packages\starlette\middleware\base.py", line 163, in call_next
    |     raise app_exc
    |   File "c:\Users\ahmed\OneDrive\Desktop\Graduation_project\venv312\Lib\site-packages\starlette\middleware\base.py", line 149, in coro
    |     await self.app(scope, receive_or_disconnect, send_no_error)
    |   File "c:\Users\ahmed\OneDrive\Desktop\Graduation_project\venv312\Lib\site-packages\starlette\middleware\cors.py", line 85, in __call__
    |     await self.app(scope, receive, send)
    |   File "c:\Users\ahmed\OneDrive\Desktop\Graduation_project\venv312\Lib\site-packages\starlette\middleware\exceptions.py", line 62, in __call__
    |     await wrap_app_handling_exceptions(self.app, conn)(scope, receive, send)
    |   File "c:\Users\ahmed\OneDrive\Desktop\Graduation_project\venv312\Lib\site-packages\starlette\_exception_handler.py", line 53, in wrapped_app
    |     raise exc
    |   File "c:\Users\ahmed\OneDrive\Desktop\Graduation_project\venv312\Lib\site-packages\starlette\_exception_handler.py", line 42, in wrapped_app
    |     await app(scope, receive, sender)
    |   File "c:\Users\ahmed\OneDrive\Desktop\Graduation_project\venv312\Lib\site-packages\starlette\routing.py", line 715, in __call__
    |     await self.middleware_stack(scope, receive, send)
    |   File "c:\Users\ahmed\OneDrive\Desktop\Graduation_project\venv312\Lib\site-packages\starlette\routing.py", line 735, in app
    |     await route.handle(scope, receive, send)
    |   File "c:\Users\ahmed\OneDrive\Desktop\Graduation_project\venv312\Lib\site-packages\starlette\routing.py", line 288, in handle
    |     await self.app(scope, receive, send)
    |   File "c:\Users\ahmed\OneDrive\Desktop\Graduation_project\venv312\Lib\site-packages\starlette\routing.py", line 76, in app
    |     await wrap_app_handling_exceptions(app, request)(scope, receive, send)
    |   File "c:\Users\ahmed\OneDrive\Desktop\Graduation_project\venv312\Lib\site-packages\starlette\_exception_handler.py", line 53, in wrapped_app
    |     raise exc
    |   File "c:\Users\ahmed\OneDrive\Desktop\Graduation_project\venv312\Lib\site-packages\starlette\_exception_handler.py", line 42, in wrapped_app
    |     await app(scope, receive, sender)
    |   File "c:\Users\ahmed\OneDrive\Desktop\Graduation_project\venv312\Lib\site-packages\starlette\routing.py", line 73, in app
    |     response = await f(request)
    |                ^^^^^^^^^^^^^^^^
    |   File "c:\Users\ahmed\OneDrive\Desktop\Graduation_project\venv312\Lib\site-packages\fastapi\routing.py", line 301, in app
    |     raw_response = await run_endpoint_function(
    |                    ^^^^^^^^^^^^^^^^^^^^^^^^^^^^
    |   File "c:\Users\ahmed\OneDrive\Desktop\Graduation_project\venv312\Lib\site-packages\fastapi\routing.py", line 212, in run_endpoint_function
    |     return await dependant.call(**values)
    |            ^^^^^^^^^^^^^^^^^^^^^^^^^^^^^^
    |   File "C:\Users\ahmed\OneDrive\Desktop\Graduation_project\src\application\routers\auth.py", line 42, in login
    |     return auth_service.login(form_data.username, form_data.password)
    |            ^^^^^^^^^^^^^^^^^^
    | AttributeError: 'AuthService' object has no attribute 'login'
    +------------------------------------

During handling of the above exception, another exception occurred:

Traceback (most recent call last):
  File "c:\Users\ahmed\OneDrive\Desktop\Graduation_project\venv312\Lib\site-packages\starlette\middleware\errors.py", line 165, in __call__
    await self.app(scope, receive, _send)
  File "c:\Users\ahmed\OneDrive\Desktop\Graduation_project\venv312\Lib\site-packages\starlette\middleware\base.py", line 185, in __call__
    with collapse_excgroups():
  File "C:\Users\ahmed\AppData\Local\Programs\Python\Python312\Lib\contextlib.py", line 158, in __exit__
    self.gen.throw(value)
  File "c:\Users\ahmed\OneDrive\Desktop\Graduation_project\venv312\Lib\site-packages\starlette\_utils.py", line 82, in collapse_excgroups
    raise exc
  File "c:\Users\ahmed\OneDrive\Desktop\Graduation_project\venv312\Lib\site-packages\starlette\middleware\base.py", line 187, in __call__
    response = await self.dispatch_func(request, call_next)
               ^^^^^^^^^^^^^^^^^^^^^^^^^^^^^^^^^^^^^^^^^^^^
  File "C:\Users\ahmed\OneDrive\Desktop\Graduation_project\src\main.py", line 114, in add_security_headers
    response = await call_next(request)
               ^^^^^^^^^^^^^^^^^^^^^^^^
  File "c:\Users\ahmed\OneDrive\Desktop\Graduation_project\venv312\Lib\site-packages\starlette\middleware\base.py", line 163, in call_next
    raise app_exc
  File "c:\Users\ahmed\OneDrive\Desktop\Graduation_project\venv312\Lib\site-packages\starlette\middleware\base.py", line 149, in coro
    await self.app(scope, receive_or_disconnect, send_no_error)
  File "c:\Users\ahmed\OneDrive\Desktop\Graduation_project\venv312\Lib\site-packages\starlette\middleware\base.py", line 185, in __call__
    with collapse_excgroups():
  File "C:\Users\ahmed\AppData\Local\Programs\Python\Python312\Lib\contextlib.py", line 158, in __exit__
    self.gen.throw(value)
  File "c:\Users\ahmed\OneDrive\Desktop\Graduation_project\venv312\Lib\site-packages\starlette\_utils.py", line 82, in collapse_excgroups
    raise exc
  File "c:\Users\ahmed\OneDrive\Desktop\Graduation_project\venv312\Lib\site-packages\starlette\middleware\base.py", line 187, in __call__
    response = await self.dispatch_func(request, call_next)
               ^^^^^^^^^^^^^^^^^^^^^^^^^^^^^^^^^^^^^^^^^^^^
  File "C:\Users\ahmed\OneDrive\Desktop\Graduation_project\src\middleware\auth_middleware.py", line 78, in __call__
    return await call_next(request)
           ^^^^^^^^^^^^^^^^^^^^^^^^
  File "c:\Users\ahmed\OneDrive\Desktop\Graduation_project\venv312\Lib\site-packages\starlette\middleware\base.py", line 163, in call_next
    raise app_exc
  File "c:\Users\ahmed\OneDrive\Desktop\Graduation_project\venv312\Lib\site-packages\starlette\middleware\base.py", line 149, in coro
    await self.app(scope, receive_or_disconnect, send_no_error)
  File "c:\Users\ahmed\OneDrive\Desktop\Graduation_project\venv312\Lib\site-packages\starlette\middleware\cors.py", line 85, in __call__
    await self.app(scope, receive, send)
  File "c:\Users\ahmed\OneDrive\Desktop\Graduation_project\venv312\Lib\site-packages\starlette\middleware\exceptions.py", line 62, in __call__
    await wrap_app_handling_exceptions(self.app, conn)(scope, receive, send)
  File "c:\Users\ahmed\OneDrive\Desktop\Graduation_project\venv312\Lib\site-packages\starlette\_exception_handler.py", line 53, in wrapped_app
    raise exc
  File "c:\Users\ahmed\OneDrive\Desktop\Graduation_project\venv312\Lib\site-packages\starlette\_exception_handler.py", line 42, in wrapped_app
    await app(scope, receive, sender)
  File "c:\Users\ahmed\OneDrive\Desktop\Graduation_project\venv312\Lib\site-packages\starlette\routing.py", line 715, in __call__
    await self.middleware_stack(scope, receive, send)
  File "c:\Users\ahmed\OneDrive\Desktop\Graduation_project\venv312\Lib\site-packages\starlette\routing.py", line 735, in app
    await route.handle(scope, receive, send)
  File "c:\Users\ahmed\OneDrive\Desktop\Graduation_project\venv312\Lib\site-packages\starlette\routing.py", line 288, in handle
    await self.app(scope, receive, send)
  File "c:\Users\ahmed\OneDrive\Desktop\Graduation_project\venv312\Lib\site-packages\starlette\routing.py", line 76, in app
    await wrap_app_handling_exceptions(app, request)(scope, receive, send)
  File "c:\Users\ahmed\OneDrive\Desktop\Graduation_project\venv312\Lib\site-packages\starlette\_exception_handler.py", line 53, in wrapped_app
    raise exc
  File "c:\Users\ahmed\OneDrive\Desktop\Graduation_project\venv312\Lib\site-packages\starlette\_exception_handler.py", line 42, in wrapped_app
    await app(scope, receive, sender)
  File "c:\Users\ahmed\OneDrive\Desktop\Graduation_project\venv312\Lib\site-packages\starlette\routing.py", line 73, in app
    response = await f(request)
               ^^^^^^^^^^^^^^^^
  File "c:\Users\ahmed\OneDrive\Desktop\Graduation_project\venv312\Lib\site-packages\fastapi\routing.py", line 301, in app
    raw_response = await run_endpoint_function(
                   ^^^^^^^^^^^^^^^^^^^^^^^^^^^^
  File "c:\Users\ahmed\OneDrive\Desktop\Graduation_project\venv312\Lib\site-packages\fastapi\routing.py", line 212, in run_endpoint_function
    return await dependant.call(**values)
           ^^^^^^^^^^^^^^^^^^^^^^^^^^^^^^
  File "C:\Users\ahmed\OneDrive\Desktop\Graduation_project\src\application\routers\auth.py", line 42, in login
    return auth_service.login(form_data.username, form_data.password)
           ^^^^^^^^^^^^^^^^^^
AttributeError: 'AuthService' object has no attribute 'login'
2024-12-01 12:08:34,343 - src.main - ERROR - Validation error: [{'type': 'missing', 'loc': ('body', 'username'), 'msg': 'Field required', 'input': {'email': 'test@example.com', 'password': 'Test@123', 'first_name': 'Test', 'last_name': 'User'}}, {'type': 'missing', 'loc': ('body', 'full_name'), 'msg': 'Field required', 'input': {'email': 'test@example.com', 'password': 'Test@123', 'first_name': 'Test', 'last_name': 'User'}}] - [C:\Users\ahmed\OneDrive\Desktop\Graduation_project\src\main.py:74]
2024-12-01 12:08:34,458 - src.main - ERROR - Unhandled error: 1 validation errors:
  {'type': 'model_attributes_type', 'loc': ('response',), 'msg': 'Input should be a valid dictionary or object to extract fields from', 'input': <coroutine object AuthService.login at 0x000001D43F690440>}
 - [C:\Users\ahmed\OneDrive\Desktop\Graduation_project\src\main.py:95]
  + Exception Group Traceback (most recent call last):
  |   File "c:\Users\ahmed\OneDrive\Desktop\Graduation_project\venv312\Lib\site-packages\starlette\_utils.py", line 76, in collapse_excgroups
  |     yield
  |   File "c:\Users\ahmed\OneDrive\Desktop\Graduation_project\venv312\Lib\site-packages\starlette\middleware\base.py", line 186, in __call__
  |     async with anyio.create_task_group() as task_group:
  |   File "c:\Users\ahmed\OneDrive\Desktop\Graduation_project\venv312\Lib\site-packages\anyio\_backends\_asyncio.py", line 763, in __aexit__
  |     raise BaseExceptionGroup(
  | ExceptionGroup: unhandled errors in a TaskGroup (1 sub-exception)
  +-+---------------- 1 ----------------
    | Traceback (most recent call last):
    |   File "c:\Users\ahmed\OneDrive\Desktop\Graduation_project\venv312\Lib\site-packages\starlette\middleware\errors.py", line 165, in __call__
    |     await self.app(scope, receive, _send)
    |   File "c:\Users\ahmed\OneDrive\Desktop\Graduation_project\venv312\Lib\site-packages\starlette\middleware\base.py", line 185, in __call__
    |     with collapse_excgroups():
    |   File "C:\Users\ahmed\AppData\Local\Programs\Python\Python312\Lib\contextlib.py", line 158, in __exit__
    |     self.gen.throw(value)
    |   File "c:\Users\ahmed\OneDrive\Desktop\Graduation_project\venv312\Lib\site-packages\starlette\_utils.py", line 82, in collapse_excgroups
    |     raise exc
    |   File "c:\Users\ahmed\OneDrive\Desktop\Graduation_project\venv312\Lib\site-packages\starlette\middleware\base.py", line 187, in __call__
    |     response = await self.dispatch_func(request, call_next)
    |                ^^^^^^^^^^^^^^^^^^^^^^^^^^^^^^^^^^^^^^^^^^^^
    |   File "C:\Users\ahmed\OneDrive\Desktop\Graduation_project\src\main.py", line 114, in add_security_headers
    |     response = await call_next(request)
    |                ^^^^^^^^^^^^^^^^^^^^^^^^
    |   File "c:\Users\ahmed\OneDrive\Desktop\Graduation_project\venv312\Lib\site-packages\starlette\middleware\base.py", line 163, in call_next
    |     raise app_exc
    |   File "c:\Users\ahmed\OneDrive\Desktop\Graduation_project\venv312\Lib\site-packages\starlette\middleware\base.py", line 149, in coro
    |     await self.app(scope, receive_or_disconnect, send_no_error)
    |   File "c:\Users\ahmed\OneDrive\Desktop\Graduation_project\venv312\Lib\site-packages\starlette\middleware\base.py", line 185, in __call__
    |     with collapse_excgroups():
    |   File "C:\Users\ahmed\AppData\Local\Programs\Python\Python312\Lib\contextlib.py", line 158, in __exit__
    |     self.gen.throw(value)
    |   File "c:\Users\ahmed\OneDrive\Desktop\Graduation_project\venv312\Lib\site-packages\starlette\_utils.py", line 82, in collapse_excgroups
    |     raise exc
    |   File "c:\Users\ahmed\OneDrive\Desktop\Graduation_project\venv312\Lib\site-packages\starlette\middleware\base.py", line 187, in __call__
    |     response = await self.dispatch_func(request, call_next)
    |                ^^^^^^^^^^^^^^^^^^^^^^^^^^^^^^^^^^^^^^^^^^^^
    |   File "C:\Users\ahmed\OneDrive\Desktop\Graduation_project\src\middleware\auth_middleware.py", line 78, in __call__
    |     return await call_next(request)
    |            ^^^^^^^^^^^^^^^^^^^^^^^^
    |   File "c:\Users\ahmed\OneDrive\Desktop\Graduation_project\venv312\Lib\site-packages\starlette\middleware\base.py", line 163, in call_next
    |     raise app_exc
    |   File "c:\Users\ahmed\OneDrive\Desktop\Graduation_project\venv312\Lib\site-packages\starlette\middleware\base.py", line 149, in coro
    |     await self.app(scope, receive_or_disconnect, send_no_error)
    |   File "c:\Users\ahmed\OneDrive\Desktop\Graduation_project\venv312\Lib\site-packages\starlette\middleware\cors.py", line 85, in __call__
    |     await self.app(scope, receive, send)
    |   File "c:\Users\ahmed\OneDrive\Desktop\Graduation_project\venv312\Lib\site-packages\starlette\middleware\exceptions.py", line 62, in __call__
    |     await wrap_app_handling_exceptions(self.app, conn)(scope, receive, send)
    |   File "c:\Users\ahmed\OneDrive\Desktop\Graduation_project\venv312\Lib\site-packages\starlette\_exception_handler.py", line 53, in wrapped_app
    |     raise exc
    |   File "c:\Users\ahmed\OneDrive\Desktop\Graduation_project\venv312\Lib\site-packages\starlette\_exception_handler.py", line 42, in wrapped_app
    |     await app(scope, receive, sender)
    |   File "c:\Users\ahmed\OneDrive\Desktop\Graduation_project\venv312\Lib\site-packages\starlette\routing.py", line 715, in __call__
    |     await self.middleware_stack(scope, receive, send)
    |   File "c:\Users\ahmed\OneDrive\Desktop\Graduation_project\venv312\Lib\site-packages\starlette\routing.py", line 735, in app
    |     await route.handle(scope, receive, send)
    |   File "c:\Users\ahmed\OneDrive\Desktop\Graduation_project\venv312\Lib\site-packages\starlette\routing.py", line 288, in handle
    |     await self.app(scope, receive, send)
    |   File "c:\Users\ahmed\OneDrive\Desktop\Graduation_project\venv312\Lib\site-packages\starlette\routing.py", line 76, in app
    |     await wrap_app_handling_exceptions(app, request)(scope, receive, send)
    |   File "c:\Users\ahmed\OneDrive\Desktop\Graduation_project\venv312\Lib\site-packages\starlette\_exception_handler.py", line 53, in wrapped_app
    |     raise exc
    |   File "c:\Users\ahmed\OneDrive\Desktop\Graduation_project\venv312\Lib\site-packages\starlette\_exception_handler.py", line 42, in wrapped_app
    |     await app(scope, receive, sender)
    |   File "c:\Users\ahmed\OneDrive\Desktop\Graduation_project\venv312\Lib\site-packages\starlette\routing.py", line 73, in app
    |     response = await f(request)
    |                ^^^^^^^^^^^^^^^^
    |   File "c:\Users\ahmed\OneDrive\Desktop\Graduation_project\venv312\Lib\site-packages\fastapi\routing.py", line 327, in app
    |     content = await serialize_response(
    |               ^^^^^^^^^^^^^^^^^^^^^^^^^
    |   File "c:\Users\ahmed\OneDrive\Desktop\Graduation_project\venv312\Lib\site-packages\fastapi\routing.py", line 176, in serialize_response
    |     raise ResponseValidationError(
    | fastapi.exceptions.ResponseValidationError: 1 validation errors:
    |   {'type': 'model_attributes_type', 'loc': ('response',), 'msg': 'Input should be a valid dictionary or object to extract fields from', 'input': <coroutine object AuthService.login at 0x000001D43F690440>}
    | 
    +------------------------------------

During handling of the above exception, another exception occurred:

Traceback (most recent call last):
  File "c:\Users\ahmed\OneDrive\Desktop\Graduation_project\venv312\Lib\site-packages\starlette\middleware\errors.py", line 165, in __call__
    await self.app(scope, receive, _send)
  File "c:\Users\ahmed\OneDrive\Desktop\Graduation_project\venv312\Lib\site-packages\starlette\middleware\base.py", line 185, in __call__
    with collapse_excgroups():
  File "C:\Users\ahmed\AppData\Local\Programs\Python\Python312\Lib\contextlib.py", line 158, in __exit__
    self.gen.throw(value)
  File "c:\Users\ahmed\OneDrive\Desktop\Graduation_project\venv312\Lib\site-packages\starlette\_utils.py", line 82, in collapse_excgroups
    raise exc
  File "c:\Users\ahmed\OneDrive\Desktop\Graduation_project\venv312\Lib\site-packages\starlette\middleware\base.py", line 187, in __call__
    response = await self.dispatch_func(request, call_next)
               ^^^^^^^^^^^^^^^^^^^^^^^^^^^^^^^^^^^^^^^^^^^^
  File "C:\Users\ahmed\OneDrive\Desktop\Graduation_project\src\main.py", line 114, in add_security_headers
    response = await call_next(request)
               ^^^^^^^^^^^^^^^^^^^^^^^^
  File "c:\Users\ahmed\OneDrive\Desktop\Graduation_project\venv312\Lib\site-packages\starlette\middleware\base.py", line 163, in call_next
    raise app_exc
  File "c:\Users\ahmed\OneDrive\Desktop\Graduation_project\venv312\Lib\site-packages\starlette\middleware\base.py", line 149, in coro
    await self.app(scope, receive_or_disconnect, send_no_error)
  File "c:\Users\ahmed\OneDrive\Desktop\Graduation_project\venv312\Lib\site-packages\starlette\middleware\base.py", line 185, in __call__
    with collapse_excgroups():
  File "C:\Users\ahmed\AppData\Local\Programs\Python\Python312\Lib\contextlib.py", line 158, in __exit__
    self.gen.throw(value)
  File "c:\Users\ahmed\OneDrive\Desktop\Graduation_project\venv312\Lib\site-packages\starlette\_utils.py", line 82, in collapse_excgroups
    raise exc
  File "c:\Users\ahmed\OneDrive\Desktop\Graduation_project\venv312\Lib\site-packages\starlette\middleware\base.py", line 187, in __call__
    response = await self.dispatch_func(request, call_next)
               ^^^^^^^^^^^^^^^^^^^^^^^^^^^^^^^^^^^^^^^^^^^^
  File "C:\Users\ahmed\OneDrive\Desktop\Graduation_project\src\middleware\auth_middleware.py", line 78, in __call__
    return await call_next(request)
           ^^^^^^^^^^^^^^^^^^^^^^^^
  File "c:\Users\ahmed\OneDrive\Desktop\Graduation_project\venv312\Lib\site-packages\starlette\middleware\base.py", line 163, in call_next
    raise app_exc
  File "c:\Users\ahmed\OneDrive\Desktop\Graduation_project\venv312\Lib\site-packages\starlette\middleware\base.py", line 149, in coro
    await self.app(scope, receive_or_disconnect, send_no_error)
  File "c:\Users\ahmed\OneDrive\Desktop\Graduation_project\venv312\Lib\site-packages\starlette\middleware\cors.py", line 85, in __call__
    await self.app(scope, receive, send)
  File "c:\Users\ahmed\OneDrive\Desktop\Graduation_project\venv312\Lib\site-packages\starlette\middleware\exceptions.py", line 62, in __call__
    await wrap_app_handling_exceptions(self.app, conn)(scope, receive, send)
  File "c:\Users\ahmed\OneDrive\Desktop\Graduation_project\venv312\Lib\site-packages\starlette\_exception_handler.py", line 53, in wrapped_app
    raise exc
  File "c:\Users\ahmed\OneDrive\Desktop\Graduation_project\venv312\Lib\site-packages\starlette\_exception_handler.py", line 42, in wrapped_app
    await app(scope, receive, sender)
  File "c:\Users\ahmed\OneDrive\Desktop\Graduation_project\venv312\Lib\site-packages\starlette\routing.py", line 715, in __call__
    await self.middleware_stack(scope, receive, send)
  File "c:\Users\ahmed\OneDrive\Desktop\Graduation_project\venv312\Lib\site-packages\starlette\routing.py", line 735, in app
    await route.handle(scope, receive, send)
  File "c:\Users\ahmed\OneDrive\Desktop\Graduation_project\venv312\Lib\site-packages\starlette\routing.py", line 288, in handle
    await self.app(scope, receive, send)
  File "c:\Users\ahmed\OneDrive\Desktop\Graduation_project\venv312\Lib\site-packages\starlette\routing.py", line 76, in app
    await wrap_app_handling_exceptions(app, request)(scope, receive, send)
  File "c:\Users\ahmed\OneDrive\Desktop\Graduation_project\venv312\Lib\site-packages\starlette\_exception_handler.py", line 53, in wrapped_app
    raise exc
  File "c:\Users\ahmed\OneDrive\Desktop\Graduation_project\venv312\Lib\site-packages\starlette\_exception_handler.py", line 42, in wrapped_app
    await app(scope, receive, sender)
  File "c:\Users\ahmed\OneDrive\Desktop\Graduation_project\venv312\Lib\site-packages\starlette\routing.py", line 73, in app
    response = await f(request)
               ^^^^^^^^^^^^^^^^
  File "c:\Users\ahmed\OneDrive\Desktop\Graduation_project\venv312\Lib\site-packages\fastapi\routing.py", line 327, in app
    content = await serialize_response(
              ^^^^^^^^^^^^^^^^^^^^^^^^^
  File "c:\Users\ahmed\OneDrive\Desktop\Graduation_project\venv312\Lib\site-packages\fastapi\routing.py", line 176, in serialize_response
    raise ResponseValidationError(
fastapi.exceptions.ResponseValidationError: 1 validation errors:
  {'type': 'model_attributes_type', 'loc': ('response',), 'msg': 'Input should be a valid dictionary or object to extract fields from', 'input': <coroutine object AuthService.login at 0x000001D43F690440>}

2024-12-01 12:21:11,515 - src.main - ERROR - Validation error: [{'type': 'missing', 'loc': ('body', 'username'), 'msg': 'Field required', 'input': {'email': 'test@example.com', 'password': 'Test@123', 'first_name': 'Test', 'last_name': 'User'}}, {'type': 'missing', 'loc': ('body', 'full_name'), 'msg': 'Field required', 'input': {'email': 'test@example.com', 'password': 'Test@123', 'first_name': 'Test', 'last_name': 'User'}}] - [C:\Users\ahmed\OneDrive\Desktop\Graduation_project\src\main.py:74]
2024-12-01 15:07:32,386 - src.main - ERROR - Validation error: [{'type': 'missing', 'loc': ('body', 'username'), 'msg': 'Field required', 'input': {'email': 'test@example.com', 'password': 'Test@123', 'full_name': 'Test User'}}] - [c:\Users\ahmed\OneDrive\Desktop\Graduation_project\src\main.py:81]
2024-12-01 15:07:32,522 - src.main - ERROR - Validation error: [{'type': 'missing', 'loc': ('body', 'username'), 'msg': 'Field required', 'input': None}] - [c:\Users\ahmed\OneDrive\Desktop\Graduation_project\src\main.py:81]
2024-12-01 16:25:24,187 - src.main - ERROR - Validation error: [{'type': 'missing', 'loc': ('body', 'username'), 'msg': 'Field required', 'input': {'email': 'test@example.com', 'password': 'Test@123', 'full_name': 'Test User'}}] - [c:\Users\ahmed\OneDrive\Desktop\Graduation_project\src\main.py:81]
2024-12-01 16:25:24,612 - src.main - ERROR - Validation error: [{'type': 'missing', 'loc': ('body', 'username'), 'msg': 'Field required', 'input': None}] - [c:\Users\ahmed\OneDrive\Desktop\Graduation_project\src\main.py:81]
